Workbook

Sheet README
A1: L3 Agent (Controller) — Reusable Solution Benchmark KPIs
A2: Zion Quality Platform · Sol PE grp1 / grp2 / grp3 · companion to wf2c_l3_agent_kpi_benchmark_light.html (sections A–E)
A4: Purpose | B4: One benchmark for every L3 AI agent, ML model, heuristic and business-logic component across STLC phases 1–10, so each capability is built once, certified, and reused by all three Sol PE groups.
A6: Sheet | B6: What it holds
A7: A_Scoring_Model | B7: Section A — six weighted dimensions, generic KPIs, scoring parameters, six mandatory gates, five eligibility tiers. Weights and thresholds here drive every formula.
A8: B_Evaluation_Flow | B8: Section B — the eight steps from registering an idea to quarterly re-benchmarking, with owner, inputs, outputs and exit criterion.
A9: C_Components | B9: Section C — the 30 L3 components: phase, type, technique, reusable I/O contract, golden benchmark set, shared services, KPI counts.
A10: C_KPI_Benchmark | B10: Section C — detailed KPI catalogue: one row per KPI per component with dimension, unit, direction, Target (Tier 1), Min floor and measurement method.
A11: D_Shared_Services | B11: Section D — ten shared platform services and a component × service usage matrix.
A12: E_Measurements | B12: Section E — enter each group's measured value per KPI; KPI scores (0–100) calculate automatically.
A13: E_Scorecard | B13: Section E — per component and group: dimension scores, composite, gates, tier and rank.
A14: E_Summary | B14: Section E — per component: leading group, composite, tier and the action for all groups.
A16: Legend
A17: Yellow fill | B17: Input cell — enter values here (E_Measurements group values, E_Scorecard gates G1–G4 and G6).
A18: Blue text | B18: Hardcoded benchmark values (weights, thresholds, KPI targets and floors) — change only with review board approval.
A19: Black text | B19: Formulas — do not overwrite.
A20: Green text | B20: Links pulled from another sheet.
A22: How to score
A23: 1 | B23: In E_Measurements, enter the measured value on the golden set for each KPI and group. Percent KPIs as percentages (e.g. 94%), Yes/No KPIs as 1 = Yes, 0 = No.
A24: 2 | B24: KPI score = 100 at or beyond Target, 60 at the Min floor, linear between, 0 beyond the floor. KPIs without a defined Min use the default tolerance in A_Scoring_Model.
A25: 3 | B25: In E_Scorecard, set gates G1–G4 and G6 to Y or N. G5 (efficacy floors) is computed. Composite, tier and rank calculate once all six dimensions have at least one measured KPI.
A26: 4 | B26: E_Summary shows the leading eligible solution per component. Tier 1 becomes the Sol PE standard.
A28: Example data | B28: Component L3-1.a (NL Req Parsing & Classification Agent) is pre-filled with ILLUSTRATIVE values for grp1, grp2 and grp3 to show the mechanics. Replace them with real benchmark results.
A29: Source | B29: All targets and floors: proposed benchmark v1.0 (wf2c page, September 2026), to be confirmed by the cross-group review board.

Sheet A_Scoring_Model
A1: A · Scoring model
A2: Six dimensions every L3 solution is measured on; weights are fixed across all 30 components so rankings are comparable
A4: Dim | B4: Dimension | C4: Weight | D4: Generic KPIs applied to every component
A5: D1 | B5: Functional efficacy | C5: 0.3 | D5: Component KPIs in C_KPI_Benchmark on the shared golden set · must beat the current manual / tool baseline · every D1 KPI ≥ Min (gate G5)
A6: D2 | B6: Reuse & genericity | C6: 0.2 | D6: Portability: ≥3 product lines (NVMe SSD, UFS, eMMC/uSD, PSSD) with ≤10% efficacy drop · ≥90% of specifics in config · versioned OpenAPI / JSON Schema I/O · uses shared services · adopted by ≥2 of 3 groups within 2 quarters · onboarding ≤2 days
A7: D3 | B7: Scalability & performance | C7: 0.15 | D7: p95 latency / throughput at component target · 10× load with ≤20% latency degradation · stateless, horizontally scalable on Zion K8s · cost per 1k runs at or below benchmark · fits on-prem GPU budget
A8: D4 | B8: Reliability & trust | C8: 0.1 | D8: Run-to-run consistency ≥95% · hallucination / fabricated output at or below target · evidence or citation on every output · availability ≥99.5% · graceful fallback to rules or a human
A9: D5 | B9: Business value | C9: 0.15 | D9: Effort saved vs manual baseline · SME accept-without-edit rate · cycle-time reduction of the STLC activity · monthly active users across groups
A10: D6 | B10: Governance & maintainability | C10: 0.1 | D10: Solution code test coverage ≥80% · Review Shield 0 critical · SAST 0 high, 0 secrets, data on-prem · model card, data sheet, README, runbook · MLOps drift monitor + registry · named owner and support SLA
B11: Total (must be 100%) | C11: =SUM(C5:C10) -> 1 | D11: =IF(ROUND(C11,4)=1,"OK — weights sum to 100%","CHECK — weights must sum to 100%") -> OK — weights sum to 100%
A13: Scoring parameters
B14: Score at or beyond Target | C14: 100 | D14: KPI score formula: 100 at/beyond Target · 60 at Min · linear between · 0 beyond Min
B15: Score at the Min floor | C15: 60
B16: Default tolerance for KPIs without a defined Min | C16: 0.2 | D16: Assumption: a KPI with no Min floor is interpolated between Target and Target relaxed by this tolerance (Yes/No and zero-target KPIs become pass / fail).
B17: Challenger margin to replace a champion (points) | C17: 5 | D17: Challenger replaces champion only if composite ≥ champion + margin and no gate regresses
A19: Mandatory gates — any failure makes a solution ineligible
A20: Gate | B20: Name | C20: Check | D20: Rule
A21: G1 | B21: Registered first | C21: Input | D21: Registered in the Zion Capability Registry before development starts; duplicate check done against existing Tier-1/Tier-2 components.
A22: G2 | B22: Reproducible benchmark | C22: Input | D22: Benchmarked on the shared golden dataset with a reproducible harness (versioned data, fixed seeds, scripted run).
A23: G3 | B23: Data stays on-prem | C23: Input | D23: Customer specs, logs and telemetry processed only through the approved on-prem LLM / Zion LLM gateway.
A24: G4 | B24: Human in the loop | C24: Input | D24: Human approval for irreversible actions: closing defects, granting access, release Go, committing healed scripts.
A25: G5 | B25: Efficacy floors met | C25: Auto | D25: Every D1 efficacy KPI at or above its Min floor (computed from E_Measurements).
A26: G6 | B26: Documentation complete | C26: Input | D26: README, I/O contract, model card, runbook, benchmark report.
A28: Eligibility tiers by composite score
A29: Tier | B29: Tier name | C29: Min composite | D29: What it means for the groups
A30: T1 | B30: Tier 1 · Certified | C30: 85 | D30: Platform standard. Mandatory reuse across grp1/2/3; new builds of this capability are blocked.
A31: T2 | B31: Tier 2 · Conditional | C31: 75 | D31: Reusable with a named improvement plan; re-benchmark in one quarter.
A32: T3 | B32: Tier 3 · Group-local | C32: 60 | D32: Usable within the owning group only; not listed in the shared catalog.
A33: T4 | B33: Tier 4 · Rework | C33: 45 | D33: Not for production use; merge effort into the leading solution.
A34: — | B34: Not eligible | C34: < T4 or gate fail | D34: Composite below the Tier 4 minimum, or any gate failed. Retire, or fix the failed gate and resubmit.
A36: Composite = Σ weight × dimension score = 0.30·D1 + 0.20·D2 + 0.15·D3 + 0.10·D4 + 0.15·D5 + 0.10·D6 · Dimension score = mean of its KPI scores · Tie-break: higher D1 → lower cost per 1k runs → more groups already adopting

Sheet B_Evaluation_Flow
A1: B · Evaluation flow
A2: From idea to certified reusable component
A4: Step | B4: Name | C4: What happens | D4: Owner | E4: Input | F4: Output | G4: Exit criterion
A5: 1 | B5: Register intent | C5: Group files the capability in the Zion Capability Registry with its L3 ID (e.g. L3-1.a). | D5: Proposing group lead | E5: Capability idea, target phase | F5: Registry entry | G5: Entry exists before any development (G1)
A6: 2 | B6: Duplicate check | C6: Registry searched for Tier-1/2 solutions of the same capability; if one exists the group extends it instead of building new. | D6: Review board + Zion platform team | E6: Registry entry | F6: Build / extend decision | G6: Decision recorded in registry
A7: 3 | B7: Build to contract | C7: Implement the reusable I/O contract and use the shared services (D_Shared_Services). | D7: Component owner | E7: L3 contract, shared services | F7: Solution + docs pack | G7: Contract tests pass; docs pack complete (G6)
A8: 4 | B8: Benchmark run | C8: Automated harness on the shared golden set produces the KPI report. | D8: Golden-set owner + component owner | E8: Solution, golden set | F8: KPI report (E_Measurements values) | G8: Reproducible run, versioned data and seeds (G2)
A9: 5 | B9: Score & gate | C9: KPI scores roll up to six dimensions and a composite; six gates checked. | D9: Component owner | E9: KPI report | F9: E_Scorecard row | G9: All six dimensions scored
A10: 6 | B10: Cross-group review | C10: grp1/2/3 leads and AI champions validate the evidence and gate status. | D10: Cross-group review board | E10: Scorecard + evidence | F10: Validated scores | G10: Board sign-off
A11: 7 | B11: Rank & publish | C11: Tier assigned; Tier 1 is published to the shared catalog as the Sol PE standard. | D11: Cross-group review board | E11: Validated scores | F11: Tier + catalog entry | G11: E_Summary updated and communicated
A12: 8 | B12: Quarterly re-benchmark | C12: Champion vs challenger on the grown golden set; challenger wins only by ≥ margin with no gate regression. | D12: Review board + all groups | E12: New submissions, updated golden set | F12: Updated tiers | G12: Re-benchmark completed each quarter

Sheet C_Components
A1: C · L3 component register — 30 components, STLC phases 1–10
A2: Reusable I/O contract, technique, golden benchmark set and shared services per component
A4: Phase | B4: Phase name | C4: L3 ID | D4: L3 component | E4: Type | F4: Technique | G4: Input (contract) | H4: Output (contract) | I4: Golden benchmark set | J4: Shared services | K4: KPIs total | L4: D1 KPIs | M4: D1 KPIs with floor
A5: 1 | B5: Requirements Analysis & Review | C5: 1.a | D5: NL Req Parsing & Classification Agent | E5: AI + HX | F5: LLM extraction + taxonomy classifier; clause-level chunking | G5: Spec / PRD (PDF, DOCX, ReqIF) | H5: Atomic requirements JSON {id, text, type, priority, source clause} | I5: 5 annotated specs (NVMe 2.0 Base, ZNS, UFS 4.0, 2 internal PRDs), ~2,500 labelled requirements | J5: LLM gateway, Spec &, golden harness | K5: =COUNTIF(C_KPI_Benchmark!$D$5:$D$546,C5) -> 19 | L5: =COUNTIFS(C_KPI_Benchmark!$D$5:$D$546,C5,C_KPI_Benchmark!$F$5:$F$546,"D1") -> 3 | M5: =COUNTIFS(C_KPI_Benchmark!$D$5:$D$546,C5,C_KPI_Benchmark!$F$5:$F$546,"D1",C_KPI_Benchmark!$P$5:$P$546,"Defined") -> 3
A6: 1 | B6: Requirements Analysis & Review | C6: 1.b | D6: Feasibility & Quality Analyzer | E6: AI + HX | F6: LLM rubric on ISO/IEC/IEEE 29148 attributes + ambiguity lexicon | G6: Atomic requirements | H6: Flags {ambiguous, untestable, incomplete, conflicting} + rewrite suggestion | I6: 800 requirements with SME-labelled 29148 defects + 120 known conflict pairs | J6: LLM gateway, Embedding &, Rule &, golden harness | K6: =COUNTIF(C_KPI_Benchmark!$D$5:$D$546,C6) -> 18 | L6: =COUNTIFS(C_KPI_Benchmark!$D$5:$D$546,C6,C_KPI_Benchmark!$F$5:$F$546,"D1") -> 4 | M6: =COUNTIFS(C_KPI_Benchmark!$D$5:$D$546,C6,C_KPI_Benchmark!$F$5:$F$546,"D1",C_KPI_Benchmark!$P$5:$P$546,"Defined") -> 4
A7: 1 | B7: Requirements Analysis & Review | C7: 1.c | D7: RTM Auto-Generator + Risk Scoring | E7: AI + HX | F7: Semantic linking + traceability graph; likelihood × impact risk heuristic | G7: Requirements + test cases | H7: RTM links {req, tc, confidence} + risk score 1–25 | I7: Curated RTMs from 2 released products (~6k links) with SME risk rankings | J7: LLM gateway, Embedding &, Risk scoring, golden harness | K7: =COUNTIF(C_KPI_Benchmark!$D$5:$D$546,C7) -> 19 | L7: =COUNTIFS(C_KPI_Benchmark!$D$5:$D$546,C7,C_KPI_Benchmark!$F$5:$F$546,"D1") -> 4 | M7: =COUNTIFS(C_KPI_Benchmark!$D$5:$D$546,C7,C_KPI_Benchmark!$F$5:$F$546,"D1",C_KPI_Benchmark!$P$5:$P$546,"Defined") -> 4
A8: 2 | B8: Test Planning | C8: 2.a | D8: Test Strategy AI Advisor | E8: AI | F8: RAG over strategy templates and past strategies + LLM drafting | G8: Scope, risk register, product type | H8: Strategy draft {levels, types, techniques, entry/exit} | I8: 20 approved historical strategies + SME scoring rubric | J8: LLM gateway, Spec &, Report &, golden harness | K8: =COUNTIF(C_KPI_Benchmark!$D$5:$D$546,C8) -> 17 | L8: =COUNTIFS(C_KPI_Benchmark!$D$5:$D$546,C8,C_KPI_Benchmark!$F$5:$F$546,"D1") -> 3 | M8: =COUNTIFS(C_KPI_Benchmark!$D$5:$D$546,C8,C_KPI_Benchmark!$F$5:$F$546,"D1",C_KPI_Benchmark!$P$5:$P$546,"Defined") -> 3
A9: 2 | B9: Test Planning | C9: 2.b | D9: Effort Estimator ML Model | E9: ML | F9: Gradient boosting / quantile regression on historical effort | G9: Features {req count, complexity, TC count, reuse %, FW delta} | H9: Person-days P10 / P50 / P90 | I9: ≥150 closed projects, planned vs actual effort, time-split hold-out | J9: MLOps pipeline, golden harness | K9: =COUNTIF(C_KPI_Benchmark!$D$5:$D$546,C9) -> 18 | L9: =COUNTIFS(C_KPI_Benchmark!$D$5:$D$546,C9,C_KPI_Benchmark!$F$5:$F$546,"D1") -> 3 | M9: =COUNTIFS(C_KPI_Benchmark!$D$5:$D$546,C9,C_KPI_Benchmark!$F$5:$F$546,"D1",C_KPI_Benchmark!$P$5:$P$546,"Defined") -> 3
A10: 2 | B10: Test Planning | C10: 2.c | D10: Risk Scoring & Plan Generator | E10: HX + AI | F10: FMEA RPN heuristic + LLM plan writer | G10: Features, risk items, strategy | H10: RPN scores, mitigations, test plan (MD / DOCX / Confluence) | I10: 15 plans with SME risk rankings and review comments | J10: LLM gateway, Risk scoring, Rule &, Report &, golden harness | K10: =COUNTIF(C_KPI_Benchmark!$D$5:$D$546,C10) -> 17 | L10: =COUNTIFS(C_KPI_Benchmark!$D$5:$D$546,C10,C_KPI_Benchmark!$F$5:$F$546,"D1") -> 3 | M10: =COUNTIFS(C_KPI_Benchmark!$D$5:$D$546,C10,C_KPI_Benchmark!$F$5:$F$546,"D1",C_KPI_Benchmark!$P$5:$P$546,"Defined") -> 3
A11: 3 | B11: Test Design & Development | C11: 3.a | D11: Scenario + LLM Test Case Gen Agent | E11: AI + HX | F11: LLM + technique heuristics (EP, BVA, pairwise, state transition) | G11: Atomic requirement + domain pack | H11: TCs {pre, steps, expected, technique, req link} | I11: NVMe Format NVM, Sanitize, Get Log Page expert suites (~1,500 TCs) + seeded mutants | J11: LLM gateway, Embedding &, golden harness | K11: =COUNTIF(C_KPI_Benchmark!$D$5:$D$546,C11) -> 19 | L11: =COUNTIFS(C_KPI_Benchmark!$D$5:$D$546,C11,C_KPI_Benchmark!$F$5:$F$546,"D1") -> 4 | M11: =COUNTIFS(C_KPI_Benchmark!$D$5:$D$546,C11,C_KPI_Benchmark!$F$5:$F$546,"D1",C_KPI_Benchmark!$P$5:$P$546,"Defined") -> 4
A12: 3 | B12: Test Design & Development | C12: 3.b | D12: BDD Writer & Data Synth Agent | E12: AI + HX | F12: LLM Gherkin writer + constraint-based / generative data synthesis | G12: TC or requirement; data schema + constraints | H12: .feature files; synthetic datasets | I12: 300 reference scenarios + 20 data schemas with constraint oracles | J12: LLM gateway, golden harness | K12: =COUNTIF(C_KPI_Benchmark!$D$5:$D$546,C12) -> 17 | L12: =COUNTIFS(C_KPI_Benchmark!$D$5:$D$546,C12,C_KPI_Benchmark!$F$5:$F$546,"D1") -> 4 | M12: =COUNTIFS(C_KPI_Benchmark!$D$5:$D$546,C12,C_KPI_Benchmark!$F$5:$F$546,"D1",C_KPI_Benchmark!$P$5:$P$546,"Defined") -> 4
A13: 3 | B13: Test Design & Development | C13: 3.c | D13: Script Dev/Review & Coverage Agent | E13: AI + HX | F13: Code LLM + static analysis + coverage-gap heuristics | G13: TC; existing scripts; coverage data | H13: Automation script; review findings; coverage-gap list | I13: 200 TC→script reference pairs + seeded-defect review set | J13: LLM gateway, Log parser, golden harness | K13: =COUNTIF(C_KPI_Benchmark!$D$5:$D$546,C13) -> 18 | L13: =COUNTIFS(C_KPI_Benchmark!$D$5:$D$546,C13,C_KPI_Benchmark!$F$5:$F$546,"D1") -> 3 | M13: =COUNTIFS(C_KPI_Benchmark!$D$5:$D$546,C13,C_KPI_Benchmark!$F$5:$F$546,"D1",C_KPI_Benchmark!$P$5:$P$546,"Defined") -> 3
A14: 3 | B14: Test Design & Development | C14: 3.d | D14: AI Code Review Agent (Review Shield) | E14: AI + HX | F14: LLM reviewer over MR diff with Graph RAG branch context, layered on SAM static analysis and linters | G14: MR diff + changed-line summary; branch Graph RAG context; static-analysis output; per-repo feature config | H14: Risk summary + capped review comments {file, line, severity, type, issue, fix} | I14: ≥200 seeded, SME-labelled defects across C/C++ firmware, Python backend and TypeScript/Angular repos + clean diffs for false-positive measurement | J14: LLM gateway, Embedding &, Log parser, Rule &, Report &, MLOps pipeline, golden harness | K14: =COUNTIF(C_KPI_Benchmark!$D$5:$D$546,C14) -> 34 | L14: =COUNTIFS(C_KPI_Benchmark!$D$5:$D$546,C14,C_KPI_Benchmark!$F$5:$F$546,"D1") -> 7 | M14: =COUNTIFS(C_KPI_Benchmark!$D$5:$D$546,C14,C_KPI_Benchmark!$F$5:$F$546,"D1",C_KPI_Benchmark!$P$5:$P$546,"Defined") -> 7
A15: 4 | B15: Test Environment Setup | C15: 4.a | D15: IaC Provisioner Agent | E15: AI + BL | F15: LLM → Terraform / Ansible + policy-as-code checks | G15: Env spec {host OS, kernel, driver, FW, tools} | H15: IaC modules + provisioned rig / VM / pod | I15: 25 reference environment specs with expected end-state | J15: LLM gateway, Rule &, golden harness | K15: =COUNTIF(C_KPI_Benchmark!$D$5:$D$546,C15) -> 18 | L15: =COUNTIFS(C_KPI_Benchmark!$D$5:$D$546,C15,C_KPI_Benchmark!$F$5:$F$546,"D1") -> 3 | M15: =COUNTIFS(C_KPI_Benchmark!$D$5:$D$546,C15,C_KPI_Benchmark!$F$5:$F$546,"D1",C_KPI_Benchmark!$P$5:$P$546,"Defined") -> 3
A16: 4 | B16: Test Environment Setup | C16: 4.b | D16: Env Validator & Drift Detector | E16: ML + BL | F16: Golden-config diff rules + anomaly model on inventory snapshots | G16: Rig inventory snapshot | H16: Health status + drift items {expected, actual} | I16: 100 seeded-drift scenarios on reference rigs | J16: Time-series anomaly, MLOps pipeline, golden harness | K16: =COUNTIF(C_KPI_Benchmark!$D$5:$D$546,C16) -> 16 | L16: =COUNTIFS(C_KPI_Benchmark!$D$5:$D$546,C16,C_KPI_Benchmark!$F$5:$F$546,"D1") -> 3 | M16: =COUNTIFS(C_KPI_Benchmark!$D$5:$D$546,C16,C_KPI_Benchmark!$F$5:$F$546,"D1",C_KPI_Benchmark!$P$5:$P$546,"Defined") -> 3
... A35: 10 | B35: Post-Release & Prod. Monitoring | C35: 10.c | D35: Hotfix Triage & MLOps Pipeline | E35: HX + ML | F35: Hotfix priority heuristic + targeted regression + champion / challenger retraining | G35: Field issues; feedback data | H35: Hotfix priority + targeted suite; retrained model versions | I35: 60 historical hotfixes | J35: MLOps pipeline, Risk scoring, golden harness | K35: =COUNTIF(C_KPI_Benchmark!$D$5:$D$546,C35) -> 17 | L35: =COUNTIFS(C_KPI_Benchmark!$D$5:$D$546,C35,C_KPI_Benchmark!$F$5:$F$546,"D1") -> 3 | M35: =COUNTIFS(C_KPI_Benchmark!$D$5:$D$546,C35,C_KPI_Benchmark!$F$5:$F$546,"D1",C_KPI_Benchmark!$P$5:$P$546,"Defined") -> 3
J38: Total KPIs | K38: =SUM(K5:K35) -> 542

Sheet C_KPI_Benchmark
A1: C · Benchmark KPIs per L3 component — STLC phases 1–10
A2: One row per KPI · Target = full score and Tier-1 requirement · Min = floor (below it the KPI scores 0; below it on a D1 KPI fails gate G5)
A4: KPI ID | B4: Phase | C4: Phase name | D4: L3 ID | E4: L3 component | F4: Dim | G4: Dimension | H4: Dim weight | I4: Scope | J4: KPI | K4: Unit | L4: Direction | M4: Cond. | N4: Target (Tier 1) | O4: Min floor | P4: Min source | Q4: Measurement method | R4: Golden benchmark set
A5: 1.a-D1-01 | B5: 1 | C5: Requirements Analysis & Review | D5: 1.a | E5: NL Req Parsing & Classification Agent | F5: D1 | G5: Functional efficacy | H5: =INDEX(A_Scoring_Model!$C$5:$C$10,MATCH(F5,A_Scoring_Model!$A$5:$A$10,0)) -> 0.3 | I5: Component-specific | J5: Atomic requirement extraction recall | K5: % | L5: Higher is better | M5: ≥ | N5: 0.95 | O5: 0.88 | P5: Defined | Q5: Automated harness run on the shared golden set | R5: 5 annotated specs (NVMe 2.0 Base, ZNS, UFS 4.0, 2 internal PRDs), ~2,500 labelled requirements
A6: 1.a-D1-02 | B6: 1 | C6: Requirements Analysis & Review | D6: 1.a | E6: NL Req Parsing & Classification Agent | F6: D1 | G6: Functional efficacy | H6: =INDEX(A_Scoring_Model!$C$5:$C$10,MATCH(F6,A_Scoring_Model!$A$5:$A$10,0)) -> 0.3 | I6: Component-specific | J6: Classification macro-F1 (func / perf / security / compliance / interface) | K6: F1 | L6: Higher is better | M6: ≥ | N6: 0.9 | O6: 0.82 | P6: Defined | Q6: Automated harness run on the shared golden set | R6: 5 annotated specs (NVMe 2.0 Base, ZNS, UFS 4.0, 2 internal PRDs), ~2,500 labelled requirements
A7: 1.a-D1-03 | B7: 1 | C7: Requirements Analysis & Review | D7: 1.a | E7: NL Req Parsing & Classification Agent | F7: D1 | G7: Functional efficacy | H7: =INDEX(A_Scoring_Model!$C$5:$C$10,MATCH(F7,A_Scoring_Model!$A$5:$A$10,0)) -> 0.3 | I7: Component-specific | J7: Source-clause traceability | K7: % | L7: Higher is better | M7: ≥ | N7: 1 | O7: 0.98 | P7: Defined | Q7: Automated harness run on the shared golden set | R7: 5 annotated specs (NVMe 2.0 Base, ZNS, UFS 4.0, 2 internal PRDs), ~2,500 labelled requirements
A8: 1.a-D2-04 | B8: 1 | C8: Requirements Analysis & Review | D8: 1.a | E8: NL Req Parsing & Classification Agent | F8: D2 | G8: Reuse & genericity | H8: =INDEX(A_Scoring_Model!$C$5:$C$10,MATCH(F8,A_Scoring_Model!$A$5:$A$10,0)) -> 0.2 | I8: Component-specific | J8: Taxonomy and rules in YAML / prompt packs, no code change per group | K8: Yes/No | L8: Higher is better | M8: ≥ | N8: 1 | P8: Default tolerance | Q8: Architecture review against the L3 contract + cross-product run
A9: 1.a-D2-05 | B9: 1 | C9: Requirements Analysis & Review | D9: 1.a | E9: NL Req Parsing & Classification Agent | F9: D2 | G9: Reuse & genericity | H9: =INDEX(A_Scoring_Model!$C$5:$C$10,MATCH(F9,A_Scoring_Model!$A$5:$A$10,0)) -> 0.2 | I9: Generic | J9: Product lines supported with ≤10% efficacy drop (NVMe SSD, UFS, eMMC/uSD, PSSD) | K9: count | L9: Higher is better | M9: ≥ | N9: 3 | O9: 2 | P9: Defined | Q9: Architecture review against the L3 contract + cross-product run
A10: 1.a-D2-06 | B10: 1 | C10: Requirements Analysis & Review | D10: 1.a | E10: NL Req Parsing & Classification Agent | F10: D2 | G10: Reuse & genericity | H10: =INDEX(A_Scoring_Model!$C$5:$C$10,MATCH(F10,A_Scoring_Model!$A$5:$A$10,0)) -> 0.2 | I10: Generic | J10: Uses Zion shared services instead of re-implementing them | K10: Yes/No | L10: Higher is better | M10: ≥ | N10: 1 | P10: Default tolerance | Q10: Architecture review against the L3 contract + cross-product run
A11: 1.a-D3-07 | B11: 1 | C11: Requirements Analysis & Review | D11: 1.a | E11: NL Req Parsing & Classification Agent | F11: D3 | G11: Scalability & performance | H11: =INDEX(A_Scoring_Model!$C$5:$C$10,MATCH(F11,A_Scoring_Model!$A$5:$A$10,0)) -> 0.15 | I11: Component-specific | J11: Throughput | K11: pages/hr | L11: Higher is better | M11: ≥ | N11: 300 | P11: Default tolerance | Q11: Load / performance test on Zion reference cluster
A12: 1.a-D3-08 | B12: 1 | C12: Requirements Analysis & Review | D12: 1.a | E12: NL Req Parsing & Classification Agent | F12: D3 | G12: Scalability & performance | H12: =INDEX(A_Scoring_Model!$C$5:$C$10,MATCH(F12,A_Scoring_Model!$A$5:$A$10,0)) -> 0.15 | I12: Component-specific | J12: p95 latency per page | K12: s | L12: Lower is better | M12: ≤ | N12: 8 | P12: Default tolerance | Q12: Load / performance test on Zion reference cluster
A13: 1.a-D3-09 | B13: 1 | C13: Requirements Analysis & Review | D13: 1.a | E13: NL Req Parsing & Classification Agent | F13: D3 | G13: Scalability & performance | H13: =INDEX(A_Scoring_Model!$C$5:$C$10,MATCH(F13,A_Scoring_Model!$A$5:$A$10,0)) -> 0.15 | I13: Generic | J13: Latency degradation at 10× load | K13: % | L13: Lower is better | M13: ≤ | N13: 0.2 | O13: 0.4 | P13: Defined | Q13: Load / performance test on Zion reference cluster
A14: 1.a-D4-10 | B14: 1 | C14: Requirements Analysis & Review | D14: 1.a | E14: NL Req Parsing & Classification Agent | F14: D4 | G14: Reliability & trust | H14: =INDEX(A_Scoring_Model!$C$5:$C$10,MATCH(F14,A_Scoring_Model!$A$5:$A$10,0)) -> 0.1 | I14: Component-specific | J14: Hallucinated requirements | K14: % | L14: Lower is better | M14: ≤ | N14: 0.01 | P14: Default tolerance | Q14: Repeat harness runs, audit log and ops monitoring
A15: 1.a-D4-11 | B15: 1 | C15: Requirements Analysis & Review | D15: 1.a | E15: NL Req Parsing & Classification Agent | F15: D4 | G15: Reliability & trust | H15: =INDEX(A_Scoring_Model!$C$5:$C$10,MATCH(F15,A_Scoring_Model!$A$5:$A$10,0)) -> 0.1 | I15: Component-specific | J15: Run-to-run agreement (temperature 0) | K15: % | L15: Higher is better | M15: ≥ | N15: 0.97 | P15: Default tolerance | Q15: Repeat harness runs, audit log and ops monitoring
A16: 1.a-D4-12 | B16: 1 | C16: Requirements Analysis & Review | D16: 1.a | E16: NL Req Parsing & Classification Agent | F16: D4 | G16: Reliability & trust | H16: =INDEX(A_Scoring_Model!$C$5:$C$10,MATCH(F16,A_Scoring_Model!$A$5:$A$10,0)) -> 0.1 | I16: Generic | J16: Service availability | K16: % | L16: Higher is better | M16: ≥ | N16: 0.995 | O16: 0.99 | P16: Defined | Q16: Repeat harness runs, audit log and ops monitoring
A17: 1.a-D5-13 | B17: 1 | C17: Requirements Analysis & Review | D17: 1.a | E17: NL Req Parsing & Classification Agent | F17: D5 | G17: Business value | H17: =INDEX(A_Scoring_Model!$C$5:$C$10,MATCH(F17,A_Scoring_Model!$A$5:$A$10,0)) -> 0.15 | I17: Component-specific | J17: Manual parsing effort reduction | K17: % | L17: Higher is better | M17: ≥ | N17: 0.6 | P17: Default tolerance | Q17: Pilot vs manual baseline, SME survey
A18: 1.a-D5-14 | B18: 1 | C18: Requirements Analysis & Review | D18: 1.a | E18: NL Req Parsing & Classification Agent | F18: D5 | G18: Business value | H18: =INDEX(A_Scoring_Model!$C$5:$C$10,MATCH(F18,A_Scoring_Model!$A$5:$A$10,0)) -> 0.15 | I18: Component-specific | J18: SME acceptance rate | K18: % | L18: Higher is better | M18: ≥ | N18: 0.85 | P18: Default tolerance | Q18: Pilot vs manual baseline, SME survey
A19: 1.a-D6-15 | B19: 1 | C19: Requirements Analysis & Review | D19: 1.a | E19: NL Req Parsing & Classification Agent | F19: D6 | G19: Governance & maintainability | H19: =INDEX(A_Scoring_Model!$C$5:$C$10,MATCH(F19,A_Scoring_Model!$A$5:$A$10,0)) -> 0.1 | I19: Generic | J19: Solution code test coverage | K19: % | L19: Higher is better | M19: ≥ | N19: 0.8 | O19: 0.6 | P19: Defined | Q19: CI reports (coverage, Review Shield, SAST) + doc review
A20: 1.a-D6-16 | B20: 1 | C20: Requirements Analysis & Review | D20: 1.a | E20: NL Req Parsing & Classification Agent | F20: D6 | G20: Governance & maintainability | H20: =INDEX(A_Scoring_Model!$C$5:$C$10,MATCH(F20,A_Scoring_Model!$A$5:$A$10,0)) -> 0.1 | I20: Generic | J20: Review Shield critical findings | K20: count | L20: Lower is better | M20: ≤ | N20: 0 | P20: Default tolerance | Q20: CI reports (coverage, Review Shield, SAST) + doc review
A21: 1.a-D6-17 | B21: 1 | C21: Requirements Analysis & Review | D21: 1.a | E21: NL Req Parsing & Classification Agent | F21: D6 | G21: Governance & maintainability | H21: =INDEX(A_Scoring_Model!$C$5:$C$10,MATCH(F21,A_Scoring_Model!$A$5:$A$10,0)) -> 0.1 | I21: Generic | J21: SAST high findings and exposed secrets | K21: count | L21: Lower is better | M21: ≤ | N21: 0 | P21: Default tolerance | Q21: CI reports (coverage, Review Shield, SAST) + doc review
A22: 1.a-D6-18 | B22: 1 | C22: Requirements Analysis & Review | D22: 1.a | E22: NL Req Parsing & Classification Agent | F22: D6 | G22: Governance & maintainability | H22: =INDEX(A_Scoring_Model!$C$5:$C$10,MATCH(F22,A_Scoring_Model!$A$5:$A$10,0)) -> 0.1 | I22: Generic | J22: Documentation pack complete (README, I/O contract, model card, runbook) | K22: Yes/No | L22: Higher is better | M22: ≥ | N22: 1 | P22: Default tolerance | Q22: CI reports (coverage, Review Shield, SAST) + doc review
A23: 1.a-D6-19 | B23: 1 | C23: Requirements Analysis & Review | D23: 1.a | E23: NL Req Parsing & Classification Agent | F23: D6 | G23: Governance & maintainability | H23: =INDEX(A_Scoring_Model!$C$5:$C$10,MATCH(F23,A_Scoring_Model!$A$5:$A$10,0)) -> 0.1 | I23: Generic | J23: Named owner and support SLA | K23: Yes/No | L23: Higher is better | M23: ≥ | N23: 1 | P23: Default tolerance | Q23: CI reports (coverage, Review Shield, SAST) + doc review
A24: 1.b-D1-01 | B24: 1 | C24: Requirements Analysis & Review | D24: 1.b | E24: Feasibility & Quality Analyzer | F24: D1 | G24: Functional efficacy | H24: =INDEX(A_Scoring_Model!$C$5:$C$10,MATCH(F24,A_Scoring_Model!$A$5:$A$10,0)) -> 0.3 | I24: Component-specific | J24: Requirement-defect detection precision | K24: ratio | L24: Higher is better | M24: ≥ | N24: 0.85 | O24: 0.75 | P24: Defined | Q24: Automated harness run on the shared golden set | R24: 800 requirements with SME-labelled 29148 defects + 120 known conflict pairs
A25: 1.b-D1-02 | B25: 1 | C25: Requirements Analysis & Review | D25: 1.b | E25: Feasibility & Quality Analyzer | F25: D1 | G25: Functional efficacy | H25: =INDEX(A_Scoring_Model!$C$5:$C$10,MATCH(F25,A_Scoring_Model!$A$5:$A$10,0)) -> 0.3 | I25: Component-specific | J25: Requirement-defect detection recall | K25: ratio | L25: Higher is better | M25: ≥ | N25: 0.8 | O25: 0.7 | P25: Defined | Q25: Automated harness run on the shared golden set | R25: 800 requirements with SME-labelled 29148 defects + 120 known conflict pairs
A26: 1.b-D1-03 | B26: 1 | C26: Requirements Analysis & Review | D26: 1.b | E26: Feasibility & Quality Analyzer | F26: D1 | G26: Functional efficacy | H26: =INDEX(A_Scoring_Model!$C$5:$C$10,MATCH(F26,A_Scoring_Model!$A$5:$A$10,0)) -> 0.3 | I26: Component-specific | J26: Conflicting-pair detection recall | K26: ratio | L26: Higher is better | M26: ≥ | N26: 0.75 | O26: 0.6 | P26: Defined | Q26: Automated harness run on the shared golden set | R26: 800 requirements with SME-labelled 29148 defects + 120 known conflict pairs
A27: 1.b-D1-04 | B27: 1 | C27: Requirements Analysis & Review | D27: 1.b | E27: Feasibility & Quality Analyzer | F27: D1 | G27: Functional efficacy | H27: =INDEX(A_Scoring_Model!$C$5:$C$10,MATCH(F27,A_Scoring_Model!$A$5:$A$10,0)) -> 0.3 | I27: Component-specific | J27: Rewrite suggestion acceptance | K27: % | L27: Higher is better | M27: ≥ | N27: 0.7 | O27: 0.55 | P27: Defined | Q27: Automated harness run on the shared golden set | R27: 800 requirements with SME-labelled 29148 defects + 120 known conflict pairs
A28: 1.b-D2-05 | B28: 1 | C28: Requirements Analysis & Review | D28: 1.b | E28: Feasibility & Quality Analyzer | F28: D2 | G28: Reuse & genericity | H28: =INDEX(A_Scoring_Model!$C$5:$C$10,MATCH(F28,A_Scoring_Model!$A$5:$A$10,0)) -> 0.2 | I28: Component-specific | J28: Pluggable rule packs (29148 + group checklists) | K28: Yes/No | L28: Higher is better | M28: ≥ | N28: 1 | P28: Default tolerance | Q28: Architecture review against the L3 contract + cross-product run
A29: 1.b-D2-06 | B29: 1 | C29: Requirements Analysis & Review | D29: 1.b | E29: Feasibility & Quality Analyzer | F29: D2 | G29: Reuse & genericity | H29: =INDEX(A_Scoring_Model!$C$5:$C$10,MATCH(F29,A_Scoring_Model!$A$5:$A$10,0)) -> 0.2 | I29: Generic | J29: Product lines supported with ≤10% efficacy drop (NVMe SSD, UFS, eMMC/uSD, PSSD) | K29: count | L29: Higher is better | M29: ≥ | N29: 3 | O29: 2 | P29: Defined | Q29: Architecture review against the L3 contract + cross-product run
A30: 1.b-D2-07 | B30: 1 | C30: Requirements Analysis & Review | D30: 1.b | E30: Feasibility & Quality Analyzer | F30: D2 | G30: Reuse & genericity | H30: =INDEX(A_Scoring_Model!$C$5:$C$10,MATCH(F30,A_Scoring_Model!$A$5:$A$10,0)) -> 0.2 | I30: Generic | J30: Uses Zion shared services instead of re-implementing them | K30: Yes/No | L30: Higher is better | M30: ≥ | N30: 1 | P30: Default tolerance | Q30: Architecture review against the L3 contract + cross-product run
A31: 1.b-D3-08 | B31: 1 | C31: Requirements Analysis & Review | D31: 1.b | E31: Feasibility & Quality Analyzer | F31: D3 | G31: Scalability & performance | H31: =INDEX(A_Scoring_Model!$C$5:$C$10,MATCH(F31,A_Scoring_Model!$A$5:$A$10,0)) -> 0.15 | I31: Component-specific | J31: Time to analyse 1,000 requirements | K31: min | L31: Lower is better | M31: ≤ | N31: 10 | P31: Default tolerance | Q31: Load / performance test on Zion reference cluster
A32: 1.b-D3-09 | B32: 1 | C32: Requirements Analysis & Review | D32: 1.b | E32: Feasibility & Quality Analyzer | F32: D3 | G32: Scalability & performance | H32: =INDEX(A_Scoring_Model!$C$5:$C$10,MATCH(F32,A_Scoring_Model!$A$5:$A$10,0)) -> 0.15 | I32: Generic | J32: Latency degradation at 10× load | K32: % | L32: Lower is better | M32: ≤ | N32: 0.2 | O32: 0.4 | P32: Defined | Q32: Load / performance test on Zion reference cluster
A33: 1.b-D4-10 | B33: 1 | C33: Requirements Analysis & Review | D33: 1.b | E33: Feasibility & Quality Analyzer | F33: D4 | G33: Reliability & trust | H33: =INDEX(A_Scoring_Model!$C$5:$C$10,MATCH(F33,A_Scoring_Model!$A$5:$A$10,0)) -> 0.1 | I33: Component-specific | J33: False alarm rate | K33: % | L33: Lower is better | M33: ≤ | N33: 0.15 | P33: Default tolerance | Q33: Repeat harness runs, audit log and ops monitoring
A34: 1.b-D4-11 | B34: 1 | C34: Requirements Analysis & Review | D34: 1.b | E34: Feasibility & Quality Analyzer | F34: D4 | G34: Reliability & trust | H34: =INDEX(A_Scoring_Model!$C$5:$C$10,MATCH(F34,A_Scoring_Model!$A$5:$A$10,0)) -> 0.1 | I34: Component-specific | J34: Flags citing rule + text span | K34: % | L34: Higher is better | M34: ≥ | N34: 1 | P34: Default tolerance | Q34: Repeat harness runs, audit log and ops monitoring
A35: 1.b-D4-12 | B35: 1 | C35: Requirements Analysis & Review | D35: 1.b | E35: Feasibility & Quality Analyzer | F35: D4 | G35: Reliability & trust | H35: =INDEX(A_Scoring_Model!$C$5:$C$10,MATCH(F35,A_Scoring_Model!$A$5:$A$10,0)) -> 0.1 | I35: Generic | J35: Service availability | K35: % | L35: Higher is better | M35: ≥ | N35: 0.995 | O35: 0.99 | P35: Defined | Q35: Repeat harness runs, audit log and ops monitoring
A36: 1.b-D5-13 | B36: 1 | C36: Requirements Analysis & Review | D36: 1.b | E36: Feasibility & Quality Analyzer | F36: D5 | G36: Business value | H36: =INDEX(A_Scoring_Model!$C$5:$C$10,MATCH(F36,A_Scoring_Model!$A$5:$A$10,0)) -> 0.15 | I36: Component-specific | J36: Requirement defects escaping into test design (reduction) | K36: % | L36: Higher is better | M36: ≥ | N36: 0.4 | P36: Default tolerance | Q36: Pilot vs manual baseline, SME survey
A37: 1.b-D6-14 | B37: 1 | C37: Requirements Analysis & Review | D37: 1.b | E37: Feasibility & Quality Analyzer | F37: D6 | G37: Governance & maintainability | H37: =INDEX(A_Scoring_Model!$C$5:$C$10,MATCH(F37,A_Scoring_Model!$A$5:$A$10,0)) -> 0.1 | I37: Generic | J37: Solution code test coverage | K37: % | L37: Higher is better | M37: ≥ | N37: 0.8 | O37: 0.6 | P37: Defined | Q37: CI reports (coverage, Review Shield, SAST) + doc review
A38: 1.b-D6-15 | B38: 1 | C38: Requirements Analysis & Review | D38: 1.b | E38: Feasibility & Quality Analyzer | F38: D6 | G38: Governance & maintainability | H38: =INDEX(A_Scoring_Model!$C$5:$C$10,MATCH(F38,A_Scoring_Model!$A$5:$A$10,0)) -> 0.1 | I38: Generic | J38: Review Shield critical findings | K38: count | L38: Lower is better | M38: ≤ | N38: 0 | P38: Default tolerance | Q38: CI reports (coverage, Review Shield, SAST) + doc review
A39: 1.b-D6-16 | B39: 1 | C39: Requirements Analysis & Review | D39: 1.b | E39: Feasibility & Quality Analyzer | F39: D6 | G39: Governance & maintainability | H39: =INDEX(A_Scoring_Model!$C$5:$C$10,MATCH(F39,A_Scoring_Model!$A$5:$A$10,0)) -> 0.1 | I39: Generic | J39: SAST high findings and exposed secrets | K39: count | L39: Lower is better | M39: ≤ | N39: 0 | P39: Default tolerance | Q39: CI reports (coverage, Review Shield, SAST) + doc review
A40: 1.b-D6-17 | B40: 1 | C40: Requirements Analysis & Review | D40: 1.b | E40: Feasibility & Quality Analyzer | F40: D6 | G40: Governance & maintainability | H40: =INDEX(A_Scoring_Model!$C$5:$C$10,MATCH(F40,A_Scoring_Model!$A$5:$A$10,0)) -> 0.1 | I40: Generic | J40: Documentation pack complete (README, I/O contract, model card, runbook) | K40: Yes/No | L40: Higher is better | M40: ≥ | N40: 1 | P40: Default tolerance | Q40: CI reports (coverage, Review Shield, SAST) + doc review
A41: 1.b-D6-18 | B41: 1 | C41: Requirements Analysis & Review | D41: 1.b | E41: Feasibility & Quality Analyzer | F41: D6 | G41: Governance & maintainability | H41: =INDEX(A_Scoring_Model!$C$5:$C$10,MATCH(F41,A_Scoring_Model!$A$5:$A$10,0)) -> 0.1 | I41: Generic | J41: Named owner and support SLA | K41: Yes/No | L41: Higher is better | M41: ≥ | N41: 1 | P41: Default tolerance | Q41: CI reports (coverage, Review Shield, SAST) + doc review
...

Sheet D_Shared_Services
A1: D · Shared building blocks — build once, reuse across components
A2: A component that re-implements a shared service scores 0 on the D2 'uses shared services' KPI
A4: Code | B4: Shared service | C4: What it provides | D4: Components using it
A5: LLM | B5: LLM gateway & prompt registry | C5: On-prem model routing, token metering, versioned prompt packs, PII / confidentiality filter | D5: =COUNTIF($D$19:$D$49,"●") -> 23
A6: EMB | B6: Embedding & semantic similarity service | C6: One embedding model and vector index for linking, dedup and retrieval | D6: =COUNTIF($E$19:$E$49,"●") -> 7
A7: SPEC | B7: Spec & document ingestion | C7: PDF / DOCX / ReqIF parsing, clause-aware chunking, table extraction | D7: =COUNTIF($F$19:$F$49,"●") -> 3
A8: RULE | B8: Rule & policy engine | C8: YAML / OPA rules for criteria, gates, access and compliance checks | D8: =COUNTIF($G$19:$G$49,"●") -> 8
A9: RISK | B9: Risk scoring library | C9: Likelihood × impact, FMEA RPN and test-impact risk in one calibrated library | D9: =COUNTIF($H$19:$H$49,"●") -> 5
A10: ANOM | B10: Time-series anomaly core | C10: SPC, change-point and isolation-forest detectors with a common alert schema | D10: =COUNTIF($I$19:$I$49,"●") -> 3
A11: LOG | B11: Log parser & signature library | C11: FW trace, host dmesg, NVMe error log, UART parsers and failure signatures | D11: =COUNTIF($J$19:$J$49,"●") -> 7
A12: DOC | B12: Report & document generator | C12: Audience templates rendered to DOCX, PPTX, Confluence and email | D12: =COUNTIF($K$19:$K$49,"●") -> 5
A13: MLOPS | B13: MLOps pipeline & model registry | C13: Feature store, training, drift monitoring, champion / challenger, rollback | D13: =COUNTIF($L$19:$L$49,"●") -> 10
A14: GOLD | B14: Golden dataset & benchmark harness | C14: Versioned golden sets, scripted runs, automatic KPI report for gate G2 | D14: =COUNTIF($M$19:$M$49,"●") -> 31
A16: Component × service usage matrix (● = uses the service)
A18: L3 ID | B18: L3 component | C18: Phase | D18: LLM | E18: EMB | F18: SPEC | G18: RULE | H18: RISK | I18: ANOM | J18: LOG | K18: DOC | L18: MLOPS | M18: GOLD
A19: 1.a | B19: NL Req Parsing & Classification Agent | C19: 1 | D19: ● | F19: ● | M19: ●
A20: 1.b | B20: Feasibility & Quality Analyzer | C20: 1 | D20: ● | E20: ● | G20: ● | M20: ●
A21: 1.c | B21: RTM Auto-Generator + Risk Scoring | C21: 1 | D21: ● | E21: ● | H21: ● | M21: ●
A22: 2.a | B22: Test Strategy AI Advisor | C22: 2 | D22: ● | F22: ● | K22: ● | M22: ●
A23: 2.b | B23: Effort Estimator ML Model | C23: 2 | L23: ● | M23: ●
A24: 2.c | B24: Risk Scoring & Plan Generator | C24: 2 | D24: ● | G24: ● | H24: ● | K24: ● | M24: ●
A25: 3.a | B25: Scenario + LLM Test Case Gen Agent | C25: 3 | D25: ● | E25: ● | M25: ●
A26: 3.b | B26: BDD Writer & Data Synth Agent | C26: 3 | D26: ● | M26: ●
A27: 3.c | B27: Script Dev/Review & Coverage Agent | C27: 3 | D27: ● | J27: ● | M27: ●
A28: 3.d | B28: AI Code Review Agent (Review Shield) | C28: 3 | D28: ● | E28: ● | G28: ● | J28: ● | K28: ● | L28: ● | M28: ●
A29: 4.a | B29: IaC Provisioner Agent | C29: 4 | D29: ● | G29: ● | M29: ●
A30: 4.b | B30: Env Validator & Drift Detector | C30: 4 | I30: ● | L30: ● | M30: ●
A31: 4.c | B31: Access & Security Recommender | C31: 4 | D31: ● | G31: ● | M31: ●
A32: 5.a | B32: Test Orchestrator Agent | C32: 5 | D32: ● | H32: ● | M32: ●
A33: 5.b | B33: Self-Healing Script Agent | C33: 5 | D33: ● | J33: ● | M33: ●
A34: 5.c | B34: Visual AI + Perf Analyzer | C34: 5 | I34: ● | L34: ● | M34: ●
A35: 6.a | B35: Defect Classifier & Severity AI | C35: 6 | D35: ● | J35: ● | L35: ● | M35: ●
A36: 6.b | B36: Duplicate Detector Agent | C36: 6 | E36: ● | J36: ● | L36: ● | M36: ●
A37: 6.c | B37: RCA Analyzer + Pattern Detector | C37: 6 | D37: ● | E37: ● | J37: ● | M37: ●
A38: 7.a | B38: Metrics Analytics Intelligence | C38: 7 | D38: ● | M38: ●
A39: 7.b | B39: Predictive QA ML Model | C39: 7 | L39: ● | M39: ●
A40: 7.c | B40: Auto Report Generator Agent | C40: 7 | D40: ● | K40: ● | M40: ●
A41: 8.a | B41: Exit Criteria Evaluator Agent | C41: 8 | D41: ● | G41: ● | M41: ●
A42: 8.b | B42: Knowledge Extractor Agent | C42: 8 | D42: ● | E42: ● | F42: ● | M42: ●
A43: 8.c | B43: Process Optimizer Agent | C43: 8 | L43: ● | M43: ●
...

Sheet E_Measurements
A1: E · Measurements — enter benchmark results per group
A2: Yellow cells = input. Percent KPIs as %, Yes/No KPIs as 1 / 0. Scores calculate automatically (100 at Target, 60 at Min, 0 beyond Min).
A4: KPI ID | B4: L3 ID | C4: L3 component | D4: Dim | E4: KPI | F4: Unit | G4: Direction | H4: Target | I4: Min (effective) | J4: grp1 value | K4: grp2 value | L4: grp3 value | M4: Sol PE platform value | N4: grp1 score | O4: grp2 score | P4: grp3 score | Q4: Sol PE platform score
A5: =C_KPI_Benchmark!A5 -> 1.a-D1-01 | B5: =C_KPI_Benchmark!D5 -> 1.a | C5: =C_KPI_Benchmark!E5 -> NL Req Parsing & Classification Agent | D5: =C_KPI_Benchmark!F5 -> D1 | E5: =C_KPI_Benchmark!J5 -> Atomic requirement extraction recall | F5: =C_KPI_Benchmark!K5 -> % | G5: =C_KPI_Benchmark!L5 -> Higher is better | H5: =C_KPI_Benchmark!N5 -> 0.95 | I5: =IF(C_KPI_Benchmark!O5<>"",C_KPI_Benchmark!O5,IF(G5="Higher is better",H5*(1-A_Scoring_Model!$C$16),H5*(1+A_Scoring_Model!$C$16))) -> 0.88 | J5: 0.92 | K5: 0.96 | L5: 0.93 | N5: =IF(J5="","",IF($H5=$I5,IF(OR(AND($G5="Higher is better",J5>=$H5),AND($G5="Lower is better",J5<=$H5)),A_Scoring_Model!$C$14,0),IF($G5="Higher is better",IF(J5>=$H5,A_Scoring_Model!$C$14,IF(J5<$I5,0,A_Scoring_Model!$C$15+(A_Scoring_Model!$C$14-A_Scoring_Model!$C$15)*(J5-$I5)/($H5-$I5))),IF(J5<=$H5,A_Scoring_Model!$C$14,IF(J5>$I5,0,A_Scoring_Model!$C$15+(A_Scoring_Model!$C$14-A_Scoring_Model!$C$15)*($I5-J5)/($I5-$H5)))))) -> 82.857143 | O5: =IF(K5="","",IF($H5=$I5,IF(OR(AND($G5="Higher is better",K5>=$H5),AND($G5="Lower is better",K5<=$H5)),A_Scoring_Model!$C$14,0),IF($G5="Higher is better",IF(K5>=$H5,A_Scoring_Model!$C$14,IF(K5<$I5,0,A_Scoring_Model!$C$15+(A_Scoring_Model!$C$14-A_Scoring_Model!$C$15)*(K5-$I5)/($H5-$I5))),IF(K5<=$H5,A_Scoring_Model!$C$14,IF(K5>$I5,0,A_Scoring_Model!$C$15+(A_Scoring_Model!$C$14-A_Scoring_Model!$C$15)*($I5-K5)/($I5-$H5)))))) -> 100 | P5: =IF(L5="","",IF($H5=$I5,IF(OR(AND($G5="Higher is better",L5>=$H5),AND($G5="Lower is better",L5<=$H5)),A_Scoring_Model!$C$14,0),IF($G5="Higher is better",IF(L5>=$H5,A_Scoring_Model!$C$14,IF(L5<$I5,0,A_Scoring_Model!$C$15+(A_Scoring_Model!$C$14-A_Scoring_Model!$C$15)*(L5-$I5)/($H5-$I5))),IF(L5<=$H5,A_Scoring_Model!$C$14,IF(L5>$I5,0,A_Scoring_Model!$C$15+(A_Scoring_Model!$C$14-A_Scoring_Model!$C$15)*($I5-L5)/($I5-$H5)))))) -> 88.571429 | Q5: =IF(M5="","",IF($H5=$I5,IF(OR(AND($G5="Higher is better",M5>=$H5),AND($G5="Lower is better",M5<=$H5)),A_Scoring_Model!$C$14,0),IF($G5="Higher is better",IF(M5>=$H5,A_Scoring_Model!$C$14,IF(M5<$I5,0,A_Scoring_Model!$C$15+(A_Scoring_Model!$C$14-A_Scoring_Model!$C$15)*(M5-$I5)/($H5-$I5))),IF(M5<=$H5,A_Scoring_Model!$C$14,IF(M5>$I5,0,A_Scoring_Model!$C$15+(A_Scoring_Model!$C$14-A_Scoring_Model!$C$15)*($I5-M5)/($I5-$H5))))))
A6: =C_KPI_Benchmark!A6 -> 1.a-D1-02 | B6: =C_KPI_Benchmark!D6 -> 1.a | C6: =C_KPI_Benchmark!E6 -> NL Req Parsing & Classification Agent | D6: =C_KPI_Benchmark!F6 -> D1 | E6: =C_KPI_Benchmark!J6 -> Classification macro-F1 (func / perf / security / compliance / interface) | F6: =C_KPI_Benchmark!K6 -> F1 | G6: =C_KPI_Benchmark!L6 -> Higher is better | H6: =C_KPI_Benchmark!N6 -> 0.9 | I6: =IF(C_KPI_Benchmark!O6<>"",C_KPI_Benchmark!O6,IF(G6="Higher is better",H6*(1-A_Scoring_Model!$C$16),H6*(1+A_Scoring_Model!$C$16))) -> 0.82 | J6: 0.86 | K6: 0.92 | L6: 0.88 | N6: =IF(J6="","",IF($H6=$I6,IF(OR(AND($G6="Higher is better",J6>=$H6),AND($G6="Lower is better",J6<=$H6)),A_Scoring_Model!$C$14,0),IF($G6="Higher is better",IF(J6>=$H6,A_Scoring_Model!$C$14,IF(J6<$I6,0,A_Scoring_Model!$C$15+(A_Scoring_Model!$C$14-A_Scoring_Model!$C$15)*(J6-$I6)/($H6-$I6))),IF(J6<=$H6,A_Scoring_Model!$C$14,IF(J6>$I6,0,A_Scoring_Model!$C$15+(A_Scoring_Model!$C$14-A_Scoring_Model!$C$15)*($I6-J6)/($I6-$H6)))))) -> 80 | O6: =IF(K6="","",IF($H6=$I6,IF(OR(AND($G6="Higher is better",K6>=$H6),AND($G6="Lower is better",K6<=$H6)),A_Scoring_Model!$C$14,0),IF($G6="Higher is better",IF(K6>=$H6,A_Scoring_Model!$C$14,IF(K6<$I6,0,A_Scoring_Model!$C$15+(A_Scoring_Model!$C$14-A_Scoring_Model!$C$15)*(K6-$I6)/($H6-$I6))),IF(K6<=$H6,A_Scoring_Model!$C$14,IF(K6>$I6,0,A_Scoring_Model!$C$15+(A_Scoring_Model!$C$14-A_Scoring_Model!$C$15)*($I6-K6)/($I6-$H6)))))) -> 100 | P6: =IF(L6="","",IF($H6=$I6,IF(OR(AND($G6="Higher is better",L6>=$H6),AND($G6="Lower is better",L6<=$H6)),A_Scoring_Model!$C$14,0),IF($G6="Higher is better",IF(L6>=$H6,A_Scoring_Model!$C$14,IF(L6<$I6,0,A_Scoring_Model!$C$15+(A_Scoring_Model!$C$14-A_Scoring_Model!$C$15)*(L6-$I6)/($H6-$I6))),IF(L6<=$H6,A_Scoring_Model!$C$14,IF(L6>$I6,0,A_Scoring_Model!$C$15+(A_Scoring_Model!$C$14-A_Scoring_Model!$C$15)*($I6-L6)/($I6-$H6)))))) -> 90 | Q6: =IF(M6="","",IF($H6=$I6,IF(OR(AND($G6="Higher is better",M6>=$H6),AND($G6="Lower is better",M6<=$H6)),A_Scoring_Model!$C$14,0),IF($G6="Higher is better",IF(M6>=$H6,A_Scoring_Model!$C$14,IF(M6<$I6,0,A_Scoring_Model!$C$15+(A_Scoring_Model!$C$14-A_Scoring_Model!$C$15)*(M6-$I6)/($H6-$I6))),IF(M6<=$H6,A_Scoring_Model!$C$14,IF(M6>$I6,0,A_Scoring_Model!$C$15+(A_Scoring_Model!$C$14-A_Scoring_Model!$C$15)*($I6-M6)/($I6-$H6))))))
A7: =C_KPI_Benchmark!A7 -> 1.a-D1-03 | B7: =C_KPI_Benchmark!D7 -> 1.a | C7: =C_KPI_Benchmark!E7 -> NL Req Parsing & Classification Agent | D7: =C_KPI_Benchmark!F7 -> D1 | E7: =C_KPI_Benchmark!J7 -> Source-clause traceability | F7: =C_KPI_Benchmark!K7 -> % | G7: =C_KPI_Benchmark!L7 -> Higher is better | H7: =C_KPI_Benchmark!N7 -> 1 | I7: =IF(C_KPI_Benchmark!O7<>"",C_KPI_Benchmark!O7,IF(G7="Higher is better",H7*(1-A_Scoring_Model!$C$16),H7*(1+A_Scoring_Model!$C$16))) -> 0.98 | J7: 0.99 | K7: 1 | L7: 1 | N7: =IF(J7="","",IF($H7=$I7,IF(OR(AND($G7="Higher is better",J7>=$H7),AND($G7="Lower is better",J7<=$H7)),A_Scoring_Model!$C$14,0),IF($G7="Higher is better",IF(J7>=$H7,A_Scoring_Model!$C$14,IF(J7<$I7,0,A_Scoring_Model!$C$15+(A_Scoring_Model!$C$14-A_Scoring_Model!$C$15)*(J7-$I7)/($H7-$I7))),IF(J7<=$H7,A_Scoring_Model!$C$14,IF(J7>$I7,0,A_Scoring_Model!$C$15+(A_Scoring_Model!$C$14-A_Scoring_Model!$C$15)*($I7-J7)/($I7-$H7)))))) -> 80 | O7: =IF(K7="","",IF($H7=$I7,IF(OR(AND($G7="Higher is better",K7>=$H7),AND($G7="Lower is better",K7<=$H7)),A_Scoring_Model!$C$14,0),IF($G7="Higher is better",IF(K7>=$H7,A_Scoring_Model!$C$14,IF(K7<$I7,0,A_Scoring_Model!$C$15+(A_Scoring_Model!$C$14-A_Scoring_Model!$C$15)*(K7-$I7)/($H7-$I7))),IF(K7<=$H7,A_Scoring_Model!$C$14,IF(K7>$I7,0,A_Scoring_Model!$C$15+(A_Scoring_Model!$C$14-A_Scoring_Model!$C$15)*($I7-K7)/($I7-$H7)))))) -> 100 | P7: =IF(L7="","",IF($H7=$I7,IF(OR(AND($G7="Higher is better",L7>=$H7),AND($G7="Lower is better",L7<=$H7)),A_Scoring_Model!$C$14,0),IF($G7="Higher is better",IF(L7>=$H7,A_Scoring_Model!$C$14,IF(L7<$I7,0,A_Scoring_Model!$C$15+(A_Scoring_Model!$C$14-A_Scoring_Model!$C$15)*(L7-$I7)/($H7-$I7))),IF(L7<=$H7,A_Scoring_Model!$C$14,IF(L7>$I7,0,A_Scoring_Model!$C$15+(A_Scoring_Model!$C$14-A_Scoring_Model!$C$15)*($I7-L7)/($I7-$H7)))))) -> 100 | Q7: =IF(M7="","",IF($H7=$I7,IF(OR(AND($G7="Higher is better",M7>=$H7),AND($G7="Lower is better",M7<=$H7)),A_Scoring_Model!$C$14,0),IF($G7="Higher is better",IF(M7>=$H7,A_Scoring_Model!$C$14,IF(M7<$I7,0,A_Scoring_Model!$C$15+(A_Scoring_Model!$C$14-A_Scoring_Model!$C$15)*(M7-$I7)/($H7-$I7))),IF(M7<=$H7,A_Scoring_Model!$C$14,IF(M7>$I7,0,A_Scoring_Model!$C$15+(A_Scoring_Model!$C$14-A_Scoring_Model!$C$15)*($I7-M7)/($I7-$H7))))))
A8: =C_KPI_Benchmark!A8 -> 1.a-D2-04 | B8: =C_KPI_Benchmark!D8 -> 1.a | C8: =C_KPI_Benchmark!E8 -> NL Req Parsing & Classification Agent | D8: =C_KPI_Benchmark!F8 -> D2 | E8: =C_KPI_Benchmark!J8 -> Taxonomy and rules in YAML / prompt packs, no code change per group | F8: =C_KPI_Benchmark!K8 -> Yes/No | G8: =C_KPI_Benchmark!L8 -> Higher is better | H8: =C_KPI_Benchmark!N8 -> 1 | I8: =IF(C_KPI_Benchmark!O8<>"",C_KPI_Benchmark!O8,IF(G8="Higher is better",H8*(1-A_Scoring_Model!$C$16),H8*(1+A_Scoring_Model!$C$16))) -> 0.8 | J8: 1 | K8: 0 | L8: 1 | N8: =IF(J8="","",IF($H8=$I8,IF(OR(AND($G8="Higher is better",J8>=$H8),AND($G8="Lower is better",J8<=$H8)),A_Scoring_Model!$C$14,0),IF($G8="Higher is better",IF(J8>=$H8,A_Scoring_Model!$C$14,IF(J8<$I8,0,A_Scoring_Model!$C$15+(A_Scoring_Model!$C$14-A_Scoring_Model!$C$15)*(J8-$I8)/($H8-$I8))),IF(J8<=$H8,A_Scoring_Model!$C$14,IF(J8>$I8,0,A_Scoring_Model!$C$15+(A_Scoring_Model!$C$14-A_Scoring_Model!$C$15)*($I8-J8)/($I8-$H8)))))) -> 100 | O8: =IF(K8="","",IF($H8=$I8,IF(OR(AND($G8="Higher is better",K8>=$H8),AND($G8="Lower is better",K8<=$H8)),A_Scoring_Model!$C$14,0),IF($G8="Higher is better",IF(K8>=$H8,A_Scoring_Model!$C$14,IF(K8<$I8,0,A_Scoring_Model!$C$15+(A_Scoring_Model!$C$14-A_Scoring_Model!$C$15)*(K8-$I8)/($H8-$I8))),IF(K8<=$H8,A_Scoring_Model!$C$14,IF(K8>$I8,0,A_Scoring_Model!$C$15+(A_Scoring_Model!$C$14-A_Scoring_Model!$C$15)*($I8-K8)/($I8-$H8)))))) -> 0 | P8: =IF(L8="","",IF($H8=$I8,IF(OR(AND($G8="Higher is better",L8>=$H8),AND($G8="Lower is better",L8<=$H8)),A_Scoring_Model!$C$14,0),IF($G8="Higher is better",IF(L8>=$H8,A_Scoring_Model!$C$14,IF(L8<$I8,0,A_Scoring_Model!$C$15+(A_Scoring_Model!$C$14-A_Scoring_Model!$C$15)*(L8-$I8)/($H8-$I8))),IF(L8<=$H8,A_Scoring_Model!$C$14,IF(L8>$I8,0,A_Scoring_Model!$C$15+(A_Scoring_Model!$C$14-A_Scoring_Model!$C$15)*($I8-L8)/($I8-$H8)))))) -> 100 | Q8: =IF(M8="","",IF($H8=$I8,IF(OR(AND($G8="Higher is better",M8>=$H8),AND($G8="Lower is better",M8<=$H8)),A_Scoring_Model!$C$14,0),IF($G8="Higher is better",IF(M8>=$H8,A_Scoring_Model!$C$14,IF(M8<$I8,0,A_Scoring_Model!$C$15+(A_Scoring_Model!$C$14-A_Scoring_Model!$C$15)*(M8-$I8)/($H8-$I8))),IF(M8<=$H8,A_Scoring_Model!$C$14,IF(M8>$I8,0,A_Scoring_Model!$C$15+(A_Scoring_Model!$C$14-A_Scoring_Model!$C$15)*($I8-M8)/($I8-$H8))))))
A9: =C_KPI_Benchmark!A9 -> 1.a-D2-05 | B9: =C_KPI_Benchmark!D9 -> 1.a | C9: =C_KPI_Benchmark!E9 -> NL Req Parsing & Classification Agent | D9: =C_KPI_Benchmark!F9 -> D2 | E9: =C_KPI_Benchmark!J9 -> Product lines supported with ≤10% efficacy drop (NVMe SSD, UFS, eMMC/uSD, PSSD) | F9: =C_KPI_Benchmark!K9 -> count | G9: =C_KPI_Benchmark!L9 -> Higher is better | H9: =C_KPI_Benchmark!N9 -> 3 | I9: =IF(C_KPI_Benchmark!O9<>"",C_KPI_Benchmark!O9,IF(G9="Higher is better",H9*(1-A_Scoring_Model!$C$16),H9*(1+A_Scoring_Model!$C$16))) -> 2 | J9: 2 | K9: 1 | L9: 3 | N9: =IF(J9="","",IF($H9=$I9,IF(OR(AND($G9="Higher is better",J9>=$H9),AND($G9="Lower is better",J9<=$H9)),A_Scoring_Model!$C$14,0),IF($G9="Higher is better",IF(J9>=$H9,A_Scoring_Model!$C$14,IF(J9<$I9,0,A_Scoring_Model!$C$15+(A_Scoring_Model!$C$14-A_Scoring_Model!$C$15)*(J9-$I9)/($H9-$I9))),IF(J9<=$H9,A_Scoring_Model!$C$14,IF(J9>$I9,0,A_Scoring_Model!$C$15+(A_Scoring_Model!$C$14-A_Scoring_Model!$C$15)*($I9-J9)/($I9-$H9)))))) -> 60 | O9: =IF(K9="","",IF($H9=$I9,IF(OR(AND($G9="Higher is better",K9>=$H9),AND($G9="Lower is better",K9<=$H9)),A_Scoring_Model!$C$14,0),IF($G9="Higher is better",IF(K9>=$H9,A_Scoring_Model!$C$14,IF(K9<$I9,0,A_Scoring_Model!$C$15+(A_Scoring_Model!$C$14-A_Scoring_Model!$C$15)*(K9-$I9)/($H9-$I9))),IF(K9<=$H9,A_Scoring_Model!$C$14,IF(K9>$I9,0,A_Scoring_Model!$C$15+(A_Scoring_Model!$C$14-A_Scoring_Model!$C$15)*($I9-K9)/($I9-$H9)))))) -> 0 | P9: =IF(L9="","",IF($H9=$I9,IF(OR(AND($G9="Higher is better",L9>=$H9),AND($G9="Lower is better",L9<=$H9)),A_Scoring_Model!$C$14,0),IF($G9="Higher is better",IF(L9>=$H9,A_Scoring_Model!$C$14,IF(L9<$I9,0,A_Scoring_Model!$C$15+(A_Scoring_Model!$C$14-A_Scoring_Model!$C$15)*(L9-$I9)/($H9-$I9))),IF(L9<=$H9,A_Scoring_Model!$C$14,IF(L9>$I9,0,A_Scoring_Model!$C$15+(A_Scoring_Model!$C$14-A_Scoring_Model!$C$15)*($I9-L9)/($I9-$H9)))))) -> 100 | Q9: =IF(M9="","",IF($H9=$I9,IF(OR(AND($G9="Higher is better",M9>=$H9),AND($G9="Lower is better",M9<=$H9)),A_Scoring_Model!$C$14,0),IF($G9="Higher is better",IF(M9>=$H9,A_Scoring_Model!$C$14,IF(M9<$I9,0,A_Scoring_Model!$C$15+(A_Scoring_Model!$C$14-A_Scoring_Model!$C$15)*(M9-$I9)/($H9-$I9))),IF(M9<=$H9,A_Scoring_Model!$C$14,IF(M9>$I9,0,A_Scoring_Model!$C$15+(A_Scoring_Model!$C$14-A_Scoring_Model!$C$15)*($I9-M9)/($I9-$H9))))))
A10: =C_KPI_Benchmark!A10 -> 1.a-D2-06 | B10: =C_KPI_Benchmark!D10 -> 1.a | C10: =C_KPI_Benchmark!E10 -> NL Req Parsing & Classification Agent | D10: =C_KPI_Benchmark!F10 -> D2 | E10: =C_KPI_Benchmark!J10 -> Uses Zion shared services instead of re-implementing them | F10: =C_KPI_Benchmark!K10 -> Yes/No | G10: =C_KPI_Benchmark!L10 -> Higher is better | H10: =C_KPI_Benchmark!N10 -> 1 | I10: =IF(C_KPI_Benchmark!O10<>"",C_KPI_Benchmark!O10,IF(G10="Higher is better",H10*(1-A_Scoring_Model!$C$16),H10*(1+A_Scoring_Model!$C$16))) -> 0.8 | J10: 1 | K10: 0 | L10: 1 | N10: =IF(J10="","",IF($H10=$I10,IF(OR(AND($G10="Higher is better",J10>=$H10),AND($G10="Lower is better",J10<=$H10)),A_Scoring_Model!$C$14,0),IF($G10="Higher is better",IF(J10>=$H10,A_Scoring_Model!$C$14,IF(J10<$I10,0,A_Scoring_Model!$C$15+(A_Scoring_Model!$C$14-A_Scoring_Model!$C$15)*(J10-$I10)/($H10-$I10))),IF(J10<=$H10,A_Scoring_Model!$C$14,IF(J10>$I10,0,A_Scoring_Model!$C$15+(A_Scoring_Model!$C$14-A_Scoring_Model!$C$15)*($I10-J10)/($I10-$H10)))))) -> 100 | O10: =IF(K10="","",IF($H10=$I10,IF(OR(AND($G10="Higher is better",K10>=$H10),AND($G10="Lower is better",K10<=$H10)),A_Scoring_Model!$C$14,0),IF($G10="Higher is better",IF(K10>=$H10,A_Scoring_Model!$C$14,IF(K10<$I10,0,A_Scoring_Model!$C$15+(A_Scoring_Model!$C$14-A_Scoring_Model!$C$15)*(K10-$I10)/($H10-$I10))),IF(K10<=$H10,A_Scoring_Model!$C$14,IF(K10>$I10,0,A_Scoring_Model!$C$15+(A_Scoring_Model!$C$14-A_Scoring_Model!$C$15)*($I10-K10)/($I10-$H10)))))) -> 0 | P10: =IF(L10="","",IF($H10=$I10,IF(OR(AND($G10="Higher is better",L10>=$H10),AND($G10="Lower is better",L10<=$H10)),A_Scoring_Model!$C$14,0),IF($G10="Higher is better",IF(L10>=$H10,A_Scoring_Model!$C$14,IF(L10<$I10,0,A_Scoring_Model!$C$15+(A_Scoring_Model!$C$14-A_Scoring_Model!$C$15)*(L10-$I10)/($H10-$I10))),IF(L10<=$H10,A_Scoring_Model!$C$14,IF(L10>$I10,0,A_Scoring_Model!$C$15+(A_Scoring_Model!$C$14-A_Scoring_Model!$C$15)*($I10-L10)/($I10-$H10)))))) -> 100 | Q10: =IF(M10="","",IF($H10=$I10,IF(OR(AND($G10="Higher is better",M10>=$H10),AND($G10="Lower is better",M10<=$H10)),A_Scoring_Model!$C$14,0),IF($G10="Higher is better",IF(M10>=$H10,A_Scoring_Model!$C$14,IF(M10<$I10,0,A_Scoring_Model!$C$15+(A_Scoring_Model!$C$14-A_Scoring_Model!$C$15)*(M10-$I10)/($H10-$I10))),IF(M10<=$H10,A_Scoring_Model!$C$14,IF(M10>$I10,0,A_Scoring_Model!$C$15+(A_Scoring_Model!$C$14-A_Scoring_Model!$C$15)*($I10-M10)/($I10-$H10))))))
A11: =C_KPI_Benchmark!A11 -> 1.a-D3-07 | B11: =C_KPI_Benchmark!D11 -> 1.a | C11: =C_KPI_Benchmark!E11 -> NL Req Parsing & Classification Agent | D11: =C_KPI_Benchmark!F11 -> D3 | E11: =C_KPI_Benchmark!J11 -> Throughput | F11: =C_KPI_Benchmark!K11 -> pages/hr | G11: =C_KPI_Benchmark!L11 -> Higher is better | H11: =C_KPI_Benchmark!N11 -> 300 | I11: =IF(C_KPI_Benchmark!O11<>"",C_KPI_Benchmark!O11,IF(G11="Higher is better",H11*(1-A_Scoring_Model!$C$16),H11*(1+A_Scoring_Model!$C$16))) -> 240 | J11: 270 | K11: 320 | L11: 290 | N11: =IF(J11="","",IF($H11=$I11,IF(OR(AND($G11="Higher is better",J11>=$H11),AND($G11="Lower is better",J11<=$H11)),A_Scoring_Model!$C$14,0),IF($G11="Higher is better",IF(J11>=$H11,A_Scoring_Model!$C$14,IF(J11<$I11,0,A_Scoring_Model!$C$15+(A_Scoring_Model!$C$14-A_Scoring_Model!$C$15)*(J11-$I11)/($H11-$I11))),IF(J11<=$H11,A_Scoring_Model!$C$14,IF(J11>$I11,0,A_Scoring_Model!$C$15+(A_Scoring_Model!$C$14-A_Scoring_Model!$C$15)*($I11-J11)/($I11-$H11)))))) -> 80 | O11: =IF(K11="","",IF($H11=$I11,IF(OR(AND($G11="Higher is better",K11>=$H11),AND($G11="Lower is better",K11<=$H11)),A_Scoring_Model!$C$14,0),IF($G11="Higher is better",IF(K11>=$H11,A_Scoring_Model!$C$14,IF(K11<$I11,0,A_Scoring_Model!$C$15+(A_Scoring_Model!$C$14-A_Scoring_Model!$C$15)*(K11-$I11)/($H11-$I11))),IF(K11<=$H11,A_Scoring_Model!$C$14,IF(K11>$I11,0,A_Scoring_Model!$C$15+(A_Scoring_Model!$C$14-A_Scoring_Model!$C$15)*($I11-K11)/($I11-$H11)))))) -> 100 | P11: =IF(L11="","",IF($H11=$I11,IF(OR(AND($G11="Higher is better",L11>=$H11),AND($G11="Lower is better",L11<=$H11)),A_Scoring_Model!$C$14,0),IF($G11="Higher is better",IF(L11>=$H11,A_Scoring_Model!$C$14,IF(L11<$I11,0,A_Scoring_Model!$C$15+(A_Scoring_Model!$C$14-A_Scoring_Model!$C$15)*(L11-$I11)/($H11-$I11))),IF(L11<=$H11,A_Scoring_Model!$C$14,IF(L11>$I11,0,A_Scoring_Model!$C$15+(A_Scoring_Model!$C$14-A_Scoring_Model!$C$15)*($I11-L11)/($I11-$H11)))))) -> 93.333333 | Q11: =IF(M11="","",IF($H11=$I11,IF(OR(AND($G11="Higher is better",M11>=$H11),AND($G11="Lower is better",M11<=$H11)),A_Scoring_Model!$C$14,0),IF($G11="Higher is better",IF(M11>=$H11,A_Scoring_Model!$C$14,IF(M11<$I11,0,A_Scoring_Model!$C$15+(A_Scoring_Model!$C$14-A_Scoring_Model!$C$15)*(M11-$I11)/($H11-$I11))),IF(M11<=$H11,A_Scoring_Model!$C$14,IF(M11>$I11,0,A_Scoring_Model!$C$15+(A_Scoring_Model!$C$14-A_Scoring_Model!$C$15)*($I11-M11)/($I11-$H11))))))
A12: =C_KPI_Benchmark!A12 -> 1.a-D3-08 | B12: =C_KPI_Benchmark!D12 -> 1.a | C12: =C_KPI_Benchmark!E12 -> NL Req Parsing & Classification Agent | D12: =C_KPI_Benchmark!F12 -> D3 | E12: =C_KPI_Benchmark!J12 -> p95 latency per page | F12: =C_KPI_Benchmark!K12 -> s | G12: =C_KPI_Benchmark!L12 -> Lower is better | H12: =C_KPI_Benchmark!N12 -> 8 | I12: =IF(C_KPI_Benchmark!O12<>"",C_KPI_Benchmark!O12,IF(G12="Higher is better",H12*(1-A_Scoring_Model!$C$16),H12*(1+A_Scoring_Model!$C$16))) -> 9.6 | J12: 9 | K12: 7 | L12: 8.3 | N12: =IF(J12="","",IF($H12=$I12,IF(OR(AND($G12="Higher is better",J12>=$H12),AND($G12="Lower is better",J12<=$H12)),A_Scoring_Model!$C$14,0),IF($G12="Higher is better",IF(J12>=$H12,A_Scoring_Model!$C$14,IF(J12<$I12,0,A_Scoring_Model!$C$15+(A_Scoring_Model!$C$14-A_Scoring_Model!$C$15)*(J12-$I12)/($H12-$I12))),IF(J12<=$H12,A_Scoring_Model!$C$14,IF(J12>$I12,0,A_Scoring_Model!$C$15+(A_Scoring_Model!$C$14-A_Scoring_Model!$C$15)*($I12-J12)/($I12-$H12)))))) -> 75 | O12: =IF(K12="","",IF($H12=$I12,IF(OR(AND($G12="Higher is better",K12>=$H12),AND($G12="Lower is better",K12<=$H12)),A_Scoring_Model!$C$14,0),IF($G12="Higher is better",IF(K12>=$H12,A_Scoring_Model!$C$14,IF(K12<$I12,0,A_Scoring_Model!$C$15+(A_Scoring_Model!$C$14-A_Scoring_Model!$C$15)*(K12-$I12)/($H12-$I12))),IF(K12<=$H12,A_Scoring_Model!$C$14,IF(K12>$I12,0,A_Scoring_Model!$C$15+(A_Scoring_Model!$C$14-A_Scoring_Model!$C$15)*($I12-K12)/($I12-$H12)))))) -> 100 | P12: =IF(L12="","",IF($H12=$I12,IF(OR(AND($G12="Higher is better",L12>=$H12),AND($G12="Lower is better",L12<=$H12)),A_Scoring_Model!$C$14,0),IF($G12="Higher is better",IF(L12>=$H12,A_Scoring_Model!$C$14,IF(L12<$I12,0,A_Scoring_Model!$C$15+(A_Scoring_Model!$C$14-A_Scoring_Model!$C$15)*(L12-$I12)/($H12-$I12))),IF(L12<=$H12,A_Scoring_Model!$C$14,IF(L12>$I12,0,A_Scoring_Model!$C$15+(A_Scoring_Model!$C$14-A_Scoring_Model!$C$15)*($I12-L12)/($I12-$H12)))))) -> 92.5 | Q12: =IF(M12="","",IF($H12=$I12,IF(OR(AND($G12="Higher is better",M12>=$H12),AND($G12="Lower is better",M12<=$H12)),A_Scoring_Model!$C$14,0),IF($G12="Higher is better",IF(M12>=$H12,A_Scoring_Model!$C$14,IF(M12<$I12,0,A_Scoring_Model!$C$15+(A_Scoring_Model!$C$14-A_Scoring_Model!$C$15)*(M12-$I12)/($H12-$I12))),IF(M12<=$H12,A_Scoring_Model!$C$14,IF(M12>$I12,0,A_Scoring_Model!$C$15+(A_Scoring_Model!$C$14-A_Scoring_Model!$C$15)*($I12-M12)/($I12-$H12))))))
