Workbook

Sheet Exec_Summary
A1: Review Shield — evaluation against the L3 Agent benchmark KPIs
A2: Capability L3-3.d · AI Code Review Agent (new) · Owner: Sol PE platform (cross-group) · Evaluated 30 September 2026
A4: Composite score now | B4: Eligibility tier | C4: Gates passed | D4: Composite after gap actions | E4: Tier after gap actions
A5: =ROUND(E_Scorecard!F11,1) -> 49.2 | B5: =E_Scorecard!C26 -> Not eligible | C5: =COUNTIF(E_Scorecard!C15:C20,"Y")&" of 6" -> 2 of 6 | D5: =ROUND(E_Scorecard!H11,1) -> 92.8 | E5: =E_Scorecard!C28 -> Tier 1 · Certified
A8: Verdict | B8: Review Shield is a working, valuable tool with a strong speed and effort-saving story, but on the benchmark it is not yet eligible for cross-group certification. Four of six gates fail, and the biggest single reason is that no golden set exists, so every efficacy figure here is an estimate rather than a measurement.
A10: What scores well
A11: Speed | B11: 2 minutes average AI review time against 11–62 minutes of manual effort; the target is ≤5 minutes.
A12: Effort saving | B12: 97.7% average human effort saving and 50 engineer-hours saved in 7 days, both well past target.
A13: Output discipline | B13: The v2 system prompt mandates exact file, line, severity, issue and concrete fix for every comment — full marks on traceability.
A14: Configurability | B14: Per-repository feature toggles (code review summary, SAM score, Pylint, comment ratio, static analysis) with no code change.
A15: Ownership | B15: Named owner, versioned and documented system prompt, advisory-only comments with human merge control.
A17: What holds it back
A18: Acceptance is zero | B18: 0 of 56 issues found in merged PRs were resolved. Whatever the cause, engineers are currently merging past the findings — this alone caps the business-value dimension and undermines the effort-saving claim.
A19: Severity inflation | B19: 96% of findings are Critical or High. The v2 prompt's severity rubric is designed to fix this and does not appear to be deployed yet.
A20: Out-of-scope comments | B20: About 64% of findings (suggestion, code quality, documentation) fall outside the six defect categories the v2 prompt whitelists — the noise that drives the acceptance problem.
A21: No benchmark evidence | B21: No seeded-defect golden set and no scripted harness, so recall, precision and hallucination rate cannot be stated as fact (gate G2).
A22: Narrow reach | B22: Bitbucket only, 11 of 58 repositories onboarded, 81% of reviews from a single team, and C++ — the firmware domain the prompt is tuned for — is only 6% of reviewed code.
A23: Not on shared services | B23: Its own Graph RAG index (148.55 MB per repo) and its own LLM path instead of the shared embedding service and LLM gateway.
A25: The path to Tier 1
A26: 1 | B26: Deploy system prompt v2 and measure the change in category mix and severity spread.
A27: 2 | B27: Build the seeded-defect golden set and the scripted harness, then re-run this evaluation on measured values.
A28: 3 | B28: Instrument resolve / dismiss / false-positive on every comment so precision and acceptance become real numbers.
A29: 4 | B29: Register L3-3.d and Review Shield in the Capability Registry and complete the documentation pack.
A30: 5 | B30: Broaden reach: SCM adapters, C/C++ firmware repositories first, and shared-service adoption.
A32: Caveat | B32: Assessed values in C_KPI_Evaluation are estimates except where the confidence column says High. They were set from the 7-day dashboard, the v2 system prompt and the issue taxonomy. The review board should treat this as a provisional self-assessment until the harness runs.

Sheet A_Scoring_Model
A1: A · Scoring model applied in this evaluation
A2: Identical to L3_Agent_Benchmark_KPIs_A-E.xlsx — six weighted dimensions, six mandatory gates, five tiers
A4: Dim | B4: Dimension | C4: Weight | D4: What it measures
A5: D1 | B5: Functional efficacy | C5: 0.3 | D5: Component KPIs on the golden set; every D1 KPI must be at or above its Min floor (gate G5)
A6: D2 | B6: Reuse & genericity | C6: 0.2 | D6: Portability across product lines and platforms, config over code, use of shared services, adoption across groups
A7: D3 | B7: Scalability & performance | C7: 0.15 | D7: Latency, throughput, cost per run, behaviour at 10× load, on-prem footprint
A8: D4 | B8: Reliability & trust | C8: 0.1 | D8: Consistency, hallucination rate, evidence on every output, availability, human-in-the-loop
A9: D5 | B9: Business value | C9: 0.15 | D9: Effort saved, acceptance by engineers, cycle-time reduction, adoption breadth
A10: D6 | B10: Governance & maintainability | C10: 0.1 | D10: Test coverage, security findings, documentation pack, model/prompt registry, named owner and SLA
B11: Total | C11: =SUM(C5:C10) -> 1 | D11: =IF(ROUND(C11,4)=1,"OK — weights sum to 100%","CHECK") -> OK — weights sum to 100%
A13: Scoring parameters
B14: Score at or beyond Target | C14: 100
B15: Score at the Min floor | C15: 60
B16: Default tolerance for KPIs without a Min | C16: 0.2
A18: Eligibility tiers
A19: Tier | B19: Tier name | C19: Min composite | D19: Consequence
A20: T1 | B20: Tier 1 · Certified | C20: 85 | D20: Platform standard; mandatory reuse across grp1/grp2/grp3.
A21: T2 | B21: Tier 2 · Conditional | C21: 75 | D21: Reusable with a named improvement plan; re-benchmark in one quarter.
A22: T3 | B22: Tier 3 · Group-local | C22: 60 | D22: Owning group only; not in the shared catalog.
A23: T4 | B23: Tier 4 · Rework | C23: 45 | D23: Not for production reuse; close the gaps and resubmit.
A24: — | B24: Not eligible | C24: — | D24: Below the Tier 4 minimum, or any gate failed.
A26: Composite = 0.30·D1 + 0.20·D2 + 0.15·D3 + 0.10·D4 + 0.15·D5 + 0.10·D6 · KPI score: 100 at/beyond Target, 60 at Min, linear between, 0 beyond Min

Sheet B_Process_Readiness
A1: B · Evaluation-process readiness
A2: Where Review Shield stands on the eight benchmark steps
A4: Step | B4: Name | C4: Status | D4: Assessment | E4: Next action
A5: 1 | B5: Register intent | C5: Not done | D5: Built before the registry existed. | E5: Register L3-3.d and Review Shield retrospectively
A6: 2 | B6: Duplicate check | C6: Partial | D6: No competing code-review solution is known in grp1/grp2/grp3, but no formal registry check exists. | E6: Run the duplicate check and record the result
A7: 3 | B7: Build to contract | C7: Partial | D7: Working product with per-repo feature configuration, but no published versioned I/O contract and no use of shared services. | E7: Publish the OpenAPI / JSON Schema contract; adopt the shared LLM gateway and embedding service
A8: 4 | B8: Benchmark run | C8: Not done | D8: No golden set, no scripted harness, no KPI report. | E8: Create the seeded-defect golden set and the harness
A9: 5 | B9: Score & gate | C9: In progress | D9: This evaluation is the first scoring pass, on estimates rather than measurements. | E9: Re-run on measured values after the first harness run
A10: 6 | B10: Cross-group review | C10: Not done | D10: Scores have not been validated by grp1/grp2/grp3 leads. | E10: Table this report at the review board
A11: 7 | B11: Rank & publish | C11: Not done | D11: No tier assigned yet. | E11: Assign a tier after the measured benchmark
A12: 8 | B12: Quarterly re-benchmark | C12: Not started | D12: No champion/challenger cycle for this capability. | E12: Schedule from the first measured round

Sheet C_Capability_Profile
A1: C · Capability profile — L3-3.d AI Code Review Agent (proposed)
A2: New L3 capability in STLC phase 3, alongside 3.a Test Case Gen, 3.b BDD/Data Synth and 3.c Script Dev/Review & Coverage
A4: Capability ID | B4: L3-3.d (proposed — to be registered)
A5: Capability name | B5: AI Code Review Agent
A6: STLC phase | B6: 3 · Test Design & Development (extends to all engineering repositories, not only test scripts)
A7: Layer | B7: L3 Agent (Controller) — AI agent + heuristics + core business logic
A8: Relationship to L3-3.c | B8: 3.c reviews and generates TEST automation scripts and coverage gaps. 3.d reviews PRODUCT and firmware code in merge requests. They share lint rules and the log/static-analysis parser but have different inputs, outputs and golden sets.
A9: Evaluated solution | B9: Review Shield (deployed, Bitbucket, 11 repositories onboarded)
A10: Owner | B10: Sol PE platform (cross-group)
A11: Technique | B11: LLM reviewer over the MR diff with Graph RAG context of the destination branch, layered on SAM static analysis, Pylint / cpplint and a comment-ratio analyser
A12: Input (contract) | B12: MR diff with changed-line summary; destination-branch Graph RAG context; pre-run static analysis output (SAM, linters); per-repo feature configuration
A13: Output (contract) | B13: Summary (risk level, top concern, counts by severity) + review comments {file, line, severity, type, issue, fix}, capped per review
A14: Defect categories in scope | B14: Memory safety · Concurrency · Data integrity and protocol correctness · Security · Functional bugs · Performance (measurable only)
A15: Explicitly out of scope | B15: Style, naming, formatting, comment quality (linters own these); complexity, duplication, module size (SAM owns these); speculative observations
... A18: Scale target | B18: ~400 developers, ~100 MRs per day; current throughput 4.6 reviews per day

Sheet C_KPI_Evaluation
A1: C · KPI-by-KPI evaluation of Review Shield against L3-3.d
A2: Assessed values are ESTIMATES unless the confidence column says High. Target state = the value expected once the gap actions in E_Gaps_Actions are done.
A4: KPI ID | B4: Dim | C4: Dimension | D4: Scope | E4: KPI | F4: Unit | G4: Direction | H4: Target (Tier 1) | I4: Min floor | J4: Assessed value | K4: Score | L4: Status | M4: Confidence | N4: Tier-1 value | O4: Tier-1 score | P4: Evidence and reasoning | Q4: Stage-1 value | R4: Stage-1 score
A5: 3.d-D1-01 | B5: D1 | C5: Functional efficacy | D5: L3-3.d | E5: Critical/High defect detection recall on a seeded-defect golden set | F5: recall | G5: Higher is better | H5: 0.85 | I5: 0.7 | J5: 0.6 | K5: =IF(J5="","",IF($H5=$I5,IF(OR(AND($G5="Higher is better",J5>=$H5),AND($G5="Lower is better",J5<=$H5)),A_Scoring_Model!$C$14,0),IF($G5="Higher is better",IF(J5>=$H5,A_Scoring_Model!$C$14,IF(J5<$I5,0,A_Scoring_Model!$C$15+(A_Scoring_Model!$C$14-A_Scoring_Model!$C$15)*(J5-$I5)/($H5-$I5))),IF(J5<=$H5,A_Scoring_Model!$C$14,IF(J5>$I5,0,A_Scoring_Model!$C$15+(A_Scoring_Model!$C$14-A_Scoring_Model!$C$15)*($I5-J5)/($I5-$H5)))))) -> 0 | L5: =IF(K5=100,"Meets target",IF(K5=0,"Below floor",IF(K5>=80,"Near target","Above floor"))) -> Below floor | M5: Low | N5: 0.82 | O5: =IF(N5="","",IF($H5=$I5,IF(OR(AND($G5="Higher is better",N5>=$H5),AND($G5="Lower is better",N5<=$H5)),A_Scoring_Model!$C$14,0),IF($G5="Higher is better",IF(N5>=$H5,A_Scoring_Model!$C$14,IF(N5<$I5,0,A_Scoring_Model!$C$15+(A_Scoring_Model!$C$14-A_Scoring_Model!$C$15)*(N5-$I5)/($H5-$I5))),IF(N5<=$H5,A_Scoring_Model!$C$14,IF(N5>$I5,0,A_Scoring_Model!$C$15+(A_Scoring_Model!$C$14-A_Scoring_Model!$C$15)*($I5-N5)/($I5-$H5)))))) -> 92 | P5: No golden set exists yet, so no measured recall. Estimated from the finding mix (92 Critical, 102 High over 49K LOC in 7 days) with no ground truth to compare against. | Q5: 0.72 | R5: =IF(Q5="","",IF($H5=$I5,IF(OR(AND($G5="Higher is better",Q5>=$H5),AND($G5="Lower is better",Q5<=$H5)),A_Scoring_Model!$C$14,0),IF($G5="Higher is better",IF(Q5>=$H5,A_Scoring_Model!$C$14,IF(Q5<$I5,0,A_Scoring_Model!$C$15+(A_Scoring_Model!$C$14-A_Scoring_Model!$C$15)*(Q5-$I5)/($H5-$I5))),IF(Q5<=$H5,A_Scoring_Model!$C$14,IF(Q5>$I5,0,A_Scoring_Model!$C$15+(A_Scoring_Model!$C$14-A_Scoring_Model!$C$15)*($I5-Q5)/($I5-$H5)))))) -> 65.333333
A6: 3.d-D1-02 | B6: D1 | C6: Functional efficacy | D6: L3-3.d | E6: Comment precision (comments that are real, actionable defects) | F6: precision | G6: Higher is better | H6: 0.8 | I6: 0.65 | J6: 0.4 | K6: =IF(J6="","",IF($H6=$I6,IF(OR(AND($G6="Higher is better",J6>=$H6),AND($G6="Lower is better",J6<=$H6)),A_Scoring_Model!$C$14,0),IF($G6="Higher is better",IF(J6>=$H6,A_Scoring_Model!$C$14,IF(J6<$I6,0,A_Scoring_Model!$C$15+(A_Scoring_Model!$C$14-A_Scoring_Model!$C$15)*(J6-$I6)/($H6-$I6))),IF(J6<=$H6,A_Scoring_Model!$C$14,IF(J6>$I6,0,A_Scoring_Model!$C$15+(A_Scoring_Model!$C$14-A_Scoring_Model!$C$15)*($I6-J6)/($I6-$H6)))))) -> 0 | L6: =IF(K6=100,"Meets target",IF(K6=0,"Below floor",IF(K6>=80,"Near target","Above floor"))) -> Below floor | M6: Low | N6: 0.72 | O6: =IF(N6="","",IF($H6=$I6,IF(OR(AND($G6="Higher is better",N6>=$H6),AND($G6="Lower is better",N6<=$H6)),A_Scoring_Model!$C$14,0),IF($G6="Higher is better",IF(N6>=$H6,A_Scoring_Model!$C$14,IF(N6<$I6,0,A_Scoring_Model!$C$15+(A_Scoring_Model!$C$14-A_Scoring_Model!$C$15)*(N6-$I6)/($H6-$I6))),IF(N6<=$H6,A_Scoring_Model!$C$14,IF(N6>$I6,0,A_Scoring_Model!$C$15+(A_Scoring_Model!$C$14-A_Scoring_Model!$C$15)*($I6-N6)/($I6-$H6)))))) -> 78.666667 | P6: Dashboard acceptance ratio 0% — 0 of 56 issues found in merged PRs were resolved. Strong indicator that developers do not treat most comments as real defects. | Q6: 0.68 | R6: =IF(Q6="","",IF($H6=$I6,IF(OR(AND($G6="Higher is better",Q6>=$H6),AND($G6="Lower is better",Q6<=$H6)),A_Scoring_Model!$C$14,0),IF($G6="Higher is better",IF(Q6>=$H6,A_Scoring_Model!$C$14,IF(Q6<$I6,0,A_Scoring_Model!$C$15+(A_Scoring_Model!$C$14-A_Scoring_Model!$C$15)*(Q6-$I6)/($H6-$I6))),IF(Q6<=$H6,A_Scoring_Model!$C$14,IF(Q6>$I6,0,A_Scoring_Model!$C$15+(A_Scoring_Model!$C$14-A_Scoring_Model!$C$15)*($I6-Q6)/($I6-$H6)))))) -> 68
A7: 3.d-D1-03 | B7: D1 | C7: Functional efficacy | D7: L3-3.d | E7: Severity classification agreement with the SME rubric | F7: agreement | G7: Higher is better | H7: 0.85 | I7: 0.7 | J7: 0.45 | K7: =IF(J7="","",IF($H7=$I7,IF(OR(AND($G7="Higher is better",J7>=$H7),AND($G7="Lower is better",J7<=$H7)),A_Scoring_Model!$C$14,0),IF($G7="Higher is better",IF(J7>=$H7,A_Scoring_Model!$C$14,IF(J7<$I7,0,A_Scoring_Model!$C$15+(A_Scoring_Model!$C$14-A_Scoring_Model!$C$15)*(J7-$I7)/($H7-$I7))),IF(J7<=$H7,A_Scoring_Model!$C$14,IF(J7>$I7,0,A_Scoring_Model!$C$15+(A_Scoring_Model!$C$14-A_Scoring_Model!$C$15)*($I7-J7)/($I7-$H7)))))) -> 0 | L7: =IF(K7=100,"Meets target",IF(K7=0,"Below floor",IF(K7>=80,"Near target","Above floor"))) -> Below floor | M7: Low | N7: 0.8 | O7: =IF(N7="","",IF($H7=$I7,IF(OR(AND($G7="Higher is better",N7>=$H7),AND($G7="Lower is better",N7<=$H7)),A_Scoring_Model!$C$14,0),IF($G7="Higher is better",IF(N7>=$H7,A_Scoring_Model!$C$14,IF(N7<$I7,0,A_Scoring_Model!$C$15+(A_Scoring_Model!$C$14-A_Scoring_Model!$C$15)*(N7-$I7)/($H7-$I7))),IF(N7<=$H7,A_Scoring_Model!$C$14,IF(N7>$I7,0,A_Scoring_Model!$C$15+(A_Scoring_Model!$C$14-A_Scoring_Model!$C$15)*($I7-N7)/($I7-$H7)))))) -> 86.666667 | P7: 96% of findings are Critical (46%) or High (50%) — severity inflation. The v2 system prompt adds a severity rubric that is not reflected in the deployed output. | Q7: 0.78 | R7: =IF(Q7="","",IF($H7=$I7,IF(OR(AND($G7="Higher is better",Q7>=$H7),AND($G7="Lower is better",Q7<=$H7)),A_Scoring_Model!$C$14,0),IF($G7="Higher is better",IF(Q7>=$H7,A_Scoring_Model!$C$14,IF(Q7<$I7,0,A_Scoring_Model!$C$15+(A_Scoring_Model!$C$14-A_Scoring_Model!$C$15)*(Q7-$I7)/($H7-$I7))),IF(Q7<=$H7,A_Scoring_Model!$C$14,IF(Q7>$I7,0,A_Scoring_Model!$C$15+(A_Scoring_Model!$C$14-A_Scoring_Model!$C$15)*($I7-Q7)/($I7-$H7)))))) -> 81.333333
A8: 3.d-D1-04 | B8: D1 | C8: Functional efficacy | D8: L3-3.d | E8: Scope compliance: comments inside the allowed defect categories | F8: % | G8: Higher is better | H8: 0.95 | I8: 0.85 | J8: 0.36 | K8: =IF(J8="","",IF($H8=$I8,IF(OR(AND($G8="Higher is better",J8>=$H8),AND($G8="Lower is better",J8<=$H8)),A_Scoring_Model!$C$14,0),IF($G8="Higher is better",IF(J8>=$H8,A_Scoring_Model!$C$14,IF(J8<$I8,0,A_Scoring_Model!$C$15+(A_Scoring_Model!$C$14-A_Scoring_Model!$C$15)*(J8-$I8)/($H8-$I8))),IF(J8<=$H8,A_Scoring_Model!$C$14,IF(J8>$I8,0,A_Scoring_Model!$C$15+(A_Scoring_Model!$C$14-A_Scoring_Model!$C$15)*($I8-J8)/($I8-$H8)))))) -> 0 | L8: =IF(K8=100,"Meets target",IF(K8=0,"Below floor",IF(K8>=80,"Near target","Above floor"))) -> Below floor | M8: Medium | N8: 0.9 | O8: =IF(N8="","",IF($H8=$I8,IF(OR(AND($G8="Higher is better",N8>=$H8),AND($G8="Lower is better",N8<=$H8)),A_Scoring_Model!$C$14,0),IF($G8="Higher is better",IF(N8>=$H8,A_Scoring_Model!$C$14,IF(N8<$I8,0,A_Scoring_Model!$C$15+(A_Scoring_Model!$C$14-A_Scoring_Model!$C$15)*(N8-$I8)/($H8-$I8))),IF(N8<=$H8,A_Scoring_Model!$C$14,IF(N8>$I8,0,A_Scoring_Model!$C$15+(A_Scoring_Model!$C$14-A_Scoring_Model!$C$15)*($I8-N8)/($I8-$H8)))))) -> 80 | P8: Issue categories: suggestion 51%, code_quality 11%, documentation 2% ≈ 64% outside the v2 whitelist (memory, concurrency, data integrity, security, functional, performance). | Q8: 0.88 | R8: =IF(Q8="","",IF($H8=$I8,IF(OR(AND($G8="Higher is better",Q8>=$H8),AND($G8="Lower is better",Q8<=$H8)),A_Scoring_Model!$C$14,0),IF($G8="Higher is better",IF(Q8>=$H8,A_Scoring_Model!$C$14,IF(Q8<$I8,0,A_Scoring_Model!$C$15+(A_Scoring_Model!$C$14-A_Scoring_Model!$C$15)*(Q8-$I8)/($H8-$I8))),IF(Q8<=$H8,A_Scoring_Model!$C$14,IF(Q8>$I8,0,A_Scoring_Model!$C$15+(A_Scoring_Model!$C$14-A_Scoring_Model!$C$15)*($I8-Q8)/($I8-$H8)))))) -> 72
A9: 3.d-D1-05 | B9: D1 | C9: Functional efficacy | D9: L3-3.d | E9: Changed-line coverage (all changed files and lines analysed) | F9: % | G9: Higher is better | H9: 1 | I9: 0.98 | J9: 0.98 | K9: =IF(J9="","",IF($H9=$I9,IF(OR(AND($G9="Higher is better",J9>=$H9),AND($G9="Lower is better",J9<=$H9)),A_Scoring_Model!$C$14,0),IF($G9="Higher is better",IF(J9>=$H9,A_Scoring_Model!$C$14,IF(J9<$I9,0,A_Scoring_Model!$C$15+(A_Scoring_Model!$C$14-A_Scoring_Model!$C$15)*(J9-$I9)/($H9-$I9))),IF(J9<=$H9,A_Scoring_Model!$C$14,IF(J9>$I9,0,A_Scoring_Model!$C$15+(A_Scoring_Model!$C$14-A_Scoring_Model!$C$15)*($I9-J9)/($I9-$H9)))))) -> 60 | L9: =IF(K9=100,"Meets target",IF(K9=0,"Below floor",IF(K9>=80,"Near target","Above floor"))) -> Above floor | M9: Medium | N9: 1 | O9: =IF(N9="","",IF($H9=$I9,IF(OR(AND($G9="Higher is better",N9>=$H9),AND($G9="Lower is better",N9<=$H9)),A_Scoring_Model!$C$14,0),IF($G9="Higher is better",IF(N9>=$H9,A_Scoring_Model!$C$14,IF(N9<$I9,0,A_Scoring_Model!$C$15+(A_Scoring_Model!$C$14-A_Scoring_Model!$C$15)*(N9-$I9)/($H9-$I9))),IF(N9<=$H9,A_Scoring_Model!$C$14,IF(N9>$I9,0,A_Scoring_Model!$C$15+(A_Scoring_Model!$C$14-A_Scoring_Model!$C$15)*($I9-N9)/($I9-$H9)))))) -> 100 | P9: Pipeline reviews the whole MR diff; a 706-LOC MR was reviewed in 2 minutes. Not verified on very large MRs or binary-heavy diffs. | Q9: 0.99 | R9: =IF(Q9="","",IF($H9=$I9,IF(OR(AND($G9="Higher is better",Q9>=$H9),AND($G9="Lower is better",Q9<=$H9)),A_Scoring_Model!$C$14,0),IF($G9="Higher is better",IF(Q9>=$H9,A_Scoring_Model!$C$14,IF(Q9<$I9,0,A_Scoring_Model!$C$15+(A_Scoring_Model!$C$14-A_Scoring_Model!$C$15)*(Q9-$I9)/($H9-$I9))),IF(Q9<=$H9,A_Scoring_Model!$C$14,IF(Q9>$I9,0,A_Scoring_Model!$C$15+(A_Scoring_Model!$C$14-A_Scoring_Model!$C$15)*($I9-Q9)/($I9-$H9)))))) -> 80
A10: 3.d-D1-06 | B10: D1 | C10: Functional efficacy | D10: L3-3.d | E10: Duplicate or repeated comments within one review | F10: % | G10: Lower is better | H10: 0.05 | I10: 0.1 | J10: 0.08 | K10: =IF(J10="","",IF($H10=$I10,IF(OR(AND($G10="Higher is better",J10>=$H10),AND($G10="Lower is better",J10<=$H10)),A_Scoring_Model!$C$14,0),IF($G10="Higher is better",IF(J10>=$H10,A_Scoring_Model!$C$14,IF(J10<$I10,0,A_Scoring_Model!$C$15+(A_Scoring_Model!$C$14-A_Scoring_Model!$C$15)*(J10-$I10)/($H10-$I10))),IF(J10<=$H10,A_Scoring_Model!$C$14,IF(J10>$I10,0,A_Scoring_Model!$C$15+(A_Scoring_Model!$C$14-A_Scoring_Model!$C$15)*($I10-J10)/($I10-$H10)))))) -> 76 | L10: =IF(K10=100,"Meets target",IF(K10=0,"Below floor",IF(K10>=80,"Near target","Above floor"))) -> Above floor | M10: Low | N10: 0.04 | O10: =IF(N10="","",IF($H10=$I10,IF(OR(AND($G10="Higher is better",N10>=$H10),AND($G10="Lower is better",N10<=$H10)),A_Scoring_Model!$C$14,0),IF($G10="Higher is better",IF(N10>=$H10,A_Scoring_Model!$C$14,IF(N10<$I10,0,A_Scoring_Model!$C$15+(A_Scoring_Model!$C$14-A_Scoring_Model!$C$15)*(N10-$I10)/($H10-$I10))),IF(N10<=$H10,A_Scoring_Model!$C$14,IF(N10>$I10,0,A_Scoring_Model!$C$15+(A_Scoring_Model!$C$14-A_Scoring_Model!$C$15)*($I10-N10)/($I10-$H10)))))) -> 100 | P10: v1 prompt duplicated every inline comment in an ACTION ITEMS table; v2 removes it. Estimated for the currently deployed behaviour. | Q10: 0.04 | R10: =IF(Q10="","",IF($H10=$I10,IF(OR(AND($G10="Higher is better",Q10>=$H10),AND($G10="Lower is better",Q10<=$H10)),A_Scoring_Model!$C$14,0),IF($G10="Higher is better",IF(Q10>=$H10,A_Scoring_Model!$C$14,IF(Q10<$I10,0,A_Scoring_Model!$C$15+(A_Scoring_Model!$C$14-A_Scoring_Model!$C$15)*(Q10-$I10)/($H10-$I10))),IF(Q10<=$H10,A_Scoring_Model!$C$14,IF(Q10>$I10,0,A_Scoring_Model!$C$15+(A_Scoring_Model!$C$14-A_Scoring_Model!$C$15)*($I10-Q10)/($I10-$H10)))))) -> 100
A11: 3.d-D1-07 | B11: D1 | C11: Functional efficacy | D11: L3-3.d | E11: Findings carrying a concrete fix (code or explicit instruction) | F11: % | G11: Higher is better | H11: 0.9 | I11: 0.75 | J11: 0.85 | K11: =IF(J11="","",IF($H11=$I11,IF(OR(AND($G11="Higher is better",J11>=$H11),AND($G11="Lower is better",J11<=$H11)),A_Scoring_Model!$C$14,0),IF($G11="Higher is better",IF(J11>=$H11,A_Scoring_Model!$C$14,IF(J11<$I11,0,A_Scoring_Model!$C$15+(A_Scoring_Model!$C$14-A_Scoring_Model!$C$15)*(J11-$I11)/($H11-$I11))),IF(J11<=$H11,A_Scoring_Model!$C$14,IF(J11>$I11,0,A_Scoring_Model!$C$15+(A_Scoring_Model!$C$14-A_Scoring_Model!$C$15)*($I11-J11)/($I11-$H11)))))) -> 86.666667 | L11: =IF(K11=100,"Meets target",IF(K11=0,"Below floor",IF(K11>=80,"Near target","Above floor"))) -> Near target | M11: Medium | N11: 0.92 | O11: =IF(N11="","",IF($H11=$I11,IF(OR(AND($G11="Higher is better",N11>=$H11),AND($G11="Lower is better",N11<=$H11)),A_Scoring_Model!$C$14,0),IF($G11="Higher is better",IF(N11>=$H11,A_Scoring_Model!$C$14,IF(N11<$I11,0,A_Scoring_Model!$C$15+(A_Scoring_Model!$C$14-A_Scoring_Model!$C$15)*(N11-$I11)/($H11-$I11))),IF(N11<=$H11,A_Scoring_Model!$C$14,IF(N11>$I11,0,A_Scoring_Model!$C$15+(A_Scoring_Model!$C$14-A_Scoring_Model!$C$15)*($I11-N11)/($I11-$H11)))))) -> 100 | P11: System prompt v2 mandates a Fix field with corrected code when ≤6 lines; dashboard shows fix suggestions for SAM, Pylint and comment-ratio features. | Q11: 0.9 | R11: =IF(Q11="","",IF($H11=$I11,IF(OR(AND($G11="Higher is better",Q11>=$H11),AND($G11="Lower is better",Q11<=$H11)),A_Scoring_Model!$C$14,0),IF($G11="Higher is better",IF(Q11>=$H11,A_Scoring_Model!$C$14,IF(Q11<$I11,0,A_Scoring_Model!$C$15+(A_Scoring_Model!$C$14-A_Scoring_Model!$C$15)*(Q11-$I11)/($H11-$I11))),IF(Q11<=$H11,A_Scoring_Model!$C$14,IF(Q11>$I11,0,A_Scoring_Model!$C$15+(A_Scoring_Model!$C$14-A_Scoring_Model!$C$15)*($I11-Q11)/($I11-$H11)))))) -> 100
A12: 3.d-D2-01 | B12: D2 | C12: Reuse & genericity | D12: L3-3.d | E12: SCM platforms supported (Bitbucket, GitHub, GitLab) | F12: count | G12: Higher is better | H12: 3 | I12: 2 | J12: 1 | K12: =IF(J12="","",IF($H12=$I12,IF(OR(AND($G12="Higher is better",J12>=$H12),AND($G12="Lower is better",J12<=$H12)),A_Scoring_Model!$C$14,0),IF($G12="Higher is better",IF(J12>=$H12,A_Scoring_Model!$C$14,IF(J12<$I12,0,A_Scoring_Model!$C$15+(A_Scoring_Model!$C$14-A_Scoring_Model!$C$15)*(J12-$I12)/($H12-$I12))),IF(J12<=$H12,A_Scoring_Model!$C$14,IF(J12>$I12,0,A_Scoring_Model!$C$15+(A_Scoring_Model!$C$14-A_Scoring_Model!$C$15)*($I12-J12)/($I12-$H12)))))) -> 0 | L12: =IF(K12=100,"Meets target",IF(K12=0,"Below floor",IF(K12>=80,"Near target","Above floor"))) -> Below floor | M12: High | N12: 2 | O12: =IF(N12="","",IF($H12=$I12,IF(OR(AND($G12="Higher is better",N12>=$H12),AND($G12="Lower is better",N12<=$H12)),A_Scoring_Model!$C$14,0),IF($G12="Higher is better",IF(N12>=$H12,A_Scoring_Model!$C$14,IF(N12<$I12,0,A_Scoring_Model!$C$15+(A_Scoring_Model!$C$14-A_Scoring_Model!$C$15)*(N12-$I12)/($H12-$I12))),IF(N12<=$H12,A_Scoring_Model!$C$14,IF(N12>$I12,0,A_Scoring_Model!$C$15+(A_Scoring_Model!$C$14-A_Scoring_Model!$C$15)*($I12-N12)/($I12-$H12)))))) -> 60 | P12: Platform distribution: Bitbucket 100% (32 of 32 reviews). No GitHub or GitLab adapter evidenced. | Q12: 1 | R12: =IF(Q12="","",IF($H12=$I12,IF(OR(AND($G12="Higher is better",Q12>=$H12),AND($G12="Lower is better",Q12<=$H12)),A_Scoring_Model!$C$14,0),IF($G12="Higher is better",IF(Q12>=$H12,A_Scoring_Model!$C$14,IF(Q12<$I12,0,A_Scoring_Model!$C$15+(A_Scoring_Model!$C$14-A_Scoring_Model!$C$15)*(Q12-$I12)/($H12-$I12))),IF(Q12<=$H12,A_Scoring_Model!$C$14,IF(Q12>$I12,0,A_Scoring_Model!$C$15+(A_Scoring_Model!$C$14-A_Scoring_Model!$C$15)*($I12-Q12)/($I12-$H12)))))) -> 0
A13: 3.d-D2-02 | B13: D2 | C13: Reuse & genericity | D13: L3-3.d | E13: Languages covered with domain-aware rules | F13: count | G13: Higher is better | H13: 4 | I13: 3 | J13: 4 | K13: =IF(J13="","",IF($H13=$I13,IF(OR(AND($G13="Higher is better",J13>=$H13),AND($G13="Lower is better",J13<=$H13)),A_Scoring_Model!$C$14,0),IF($G13="Higher is better",IF(J13>=$H13,A_Scoring_Model!$C$14,IF(J13<$I13,0,A_Scoring_Model!$C$15+(A_Scoring_Model!$C$14-A_Scoring_Model!$C$15)*(J13-$I13)/($H13-$I13))),IF(J13<=$H13,A_Scoring_Model!$C$14,IF(J13>$I13,0,A_Scoring_Model!$C$15+(A_Scoring_Model!$C$14-A_Scoring_Model!$C$15)*($I13-J13)/($I13-$H13)))))) -> 100 | L13: =IF(K13=100,"Meets target",IF(K13=0,"Below floor",IF(K13>=80,"Near target","Above floor"))) -> Meets target | M13: High | N13: 5 | O13: =IF(N13="","",IF($H13=$I13,IF(OR(AND($G13="Higher is better",N13>=$H13),AND($G13="Lower is better",N13<=$H13)),A_Scoring_Model!$C$14,0),IF($G13="Higher is better",IF(N13>=$H13,A_Scoring_Model!$C$14,IF(N13<$I13,0,A_Scoring_Model!$C$15+(A_Scoring_Model!$C$14-A_Scoring_Model!$C$15)*(N13-$I13)/($H13-$I13))),IF(N13<=$H13,A_Scoring_Model!$C$14,IF(N13>$I13,0,A_Scoring_Model!$C$15+(A_Scoring_Model!$C$14-A_Scoring_Model!$C$15)*($I13-N13)/($I13-$H13)))))) -> 100 | P13: Language distribution in period: Angular/TypeScript 41%, Python 38%, JavaScript 16%, C++ 6%. | Q13: 4 | R13: =IF(Q13="","",IF($H13=$I13,IF(OR(AND($G13="Higher is better",Q13>=$H13),AND($G13="Lower is better",Q13<=$H13)),A_Scoring_Model!$C$14,0),IF($G13="Higher is better",IF(Q13>=$H13,A_Scoring_Model!$C$14,IF(Q13<$I13,0,A_Scoring_Model!$C$15+(A_Scoring_Model!$C$14-A_Scoring_Model!$C$15)*(Q13-$I13)/($H13-$I13))),IF(Q13<=$H13,A_Scoring_Model!$C$14,IF(Q13>$I13,0,A_Scoring_Model!$C$15+(A_Scoring_Model!$C$14-A_Scoring_Model!$C$15)*($I13-Q13)/($I13-$H13)))))) -> 100
A14: 3.d-D2-03 | B14: D2 | C14: Reuse & genericity | D14: L3-3.d | E14: Per-repository feature configuration without code change | F14: Yes/No | G14: Higher is better | H14: 1 | I14: =IF(G14="Higher is better",H14*(1-A_Scoring_Model!$C$16),H14*(1+A_Scoring_Model!$C$16)) -> 0.8 | J14: 1 | K14: =IF(J14="","",IF($H14=$I14,IF(OR(AND($G14="Higher is better",J14>=$H14),AND($G14="Lower is better",J14<=$H14)),A_Scoring_Model!$C$14,0),IF($G14="Higher is better",IF(J14>=$H14,A_Scoring_Model!$C$14,IF(J14<$I14,0,A_Scoring_Model!$C$15+(A_Scoring_Model!$C$14-A_Scoring_Model!$C$15)*(J14-$I14)/($H14-$I14))),IF(J14<=$H14,A_Scoring_Model!$C$14,IF(J14>$I14,0,A_Scoring_Model!$C$15+(A_Scoring_Model!$C$14-A_Scoring_Model!$C$15)*($I14-J14)/($I14-$H14)))))) -> 100 | L14: =IF(K14=100,"Meets target",IF(K14=0,"Below floor",IF(K14>=80,"Near target","Above floor"))) -> Meets target | M14: High | N14: 1 | O14: =IF(N14="","",IF($H14=$I14,IF(OR(AND($G14="Higher is better",N14>=$H14),AND($G14="Lower is better",N14<=$H14)),A_Scoring_Model!$C$14,0),IF($G14="Higher is better",IF(N14>=$H14,A_Scoring_Model!$C$14,IF(N14<$I14,0,A_Scoring_Model!$C$15+(A_Scoring_Model!$C$14-A_Scoring_Model!$C$15)*(N14-$I14)/($H14-$I14))),IF(N14<=$H14,A_Scoring_Model!$C$14,IF(N14>$I14,0,A_Scoring_Model!$C$15+(A_Scoring_Model!$C$14-A_Scoring_Model!$C$15)*($I14-N14)/($I14-$H14)))))) -> 100 | P14: Configure Features dialog exposes 5 independent toggles per repo (Code Review Summary, SAM Score, Pylint, Comment Ratio, Static Code Analysis). | Q14: 1 | R14: =IF(Q14="","",IF($H14=$I14,IF(OR(AND($G14="Higher is better",Q14>=$H14),AND($G14="Lower is better",Q14<=$H14)),A_Scoring_Model!$C$14,0),IF($G14="Higher is better",IF(Q14>=$H14,A_Scoring_Model!$C$14,IF(Q14<$I14,0,A_Scoring_Model!$C$15+(A_Scoring_Model!$C$14-A_Scoring_Model!$C$15)*(Q14-$I14)/($H14-$I14))),IF(Q14<=$H14,A_Scoring_Model!$C$14,IF(Q14>$I14,0,A_Scoring_Model!$C$15+(A_Scoring_Model!$C$14-A_Scoring_Model!$C$15)*($I14-Q14)/($I14-$H14)))))) -> 100
A15: 3.d-D2-04 | B15: D2 | C15: Reuse & genericity | D15: L3-3.d | E15: Sol PE groups with active usage | F15: groups | G15: Higher is better | H15: 2 | I15: 1 | J15: 2 | K15: =IF(J15="","",IF($H15=$I15,IF(OR(AND($G15="Higher is better",J15>=$H15),AND($G15="Lower is better",J15<=$H15)),A_Scoring_Model!$C$14,0),IF($G15="Higher is better",IF(J15>=$H15,A_Scoring_Model!$C$14,IF(J15<$I15,0,A_Scoring_Model!$C$15+(A_Scoring_Model!$C$14-A_Scoring_Model!$C$15)*(J15-$I15)/($H15-$I15))),IF(J15<=$H15,A_Scoring_Model!$C$14,IF(J15>$I15,0,A_Scoring_Model!$C$15+(A_Scoring_Model!$C$14-A_Scoring_Model!$C$15)*($I15-J15)/($I15-$H15)))))) -> 100 | L15: =IF(K15=100,"Meets target",IF(K15=0,"Below floor",IF(K15>=80,"Near target","Above floor"))) -> Meets target | M15: Medium | N15: 2 | O15: =IF(N15="","",IF($H15=$I15,IF(OR(AND($G15="Higher is better",N15>=$H15),AND($G15="Lower is better",N15<=$H15)),A_Scoring_Model!$C$14,0),IF($G15="Higher is better",IF(N15>=$H15,A_Scoring_Model!$C$14,IF(N15<$I15,0,A_Scoring_Model!$C$15+(A_Scoring_Model!$C$14-A_Scoring_Model!$C$15)*(N15-$I15)/($H15-$I15))),IF(N15<=$H15,A_Scoring_Model!$C$14,IF(N15>$I15,0,A_Scoring_Model!$C$15+(A_Scoring_Model!$C$14-A_Scoring_Model!$C$15)*($I15-N15)/($I15-$H15)))))) -> 100 | P15: Four teams appear (MQPEAS 81%, QVP 9%, MQEMMC 6%, NVMETS 3%) but usage is concentrated in one team; group-level mapping not confirmed. | Q15: 2 | R15: =IF(Q15="","",IF($H15=$I15,IF(OR(AND($G15="Higher is better",Q15>=$H15),AND($G15="Lower is better",Q15<=$H15)),A_Scoring_Model!$C$14,0),IF($G15="Higher is better",IF(Q15>=$H15,A_Scoring_Model!$C$14,IF(Q15<$I15,0,A_Scoring_Model!$C$15+(A_Scoring_Model!$C$14-A_Scoring_Model!$C$15)*(Q15-$I15)/($H15-$I15))),IF(Q15<=$H15,A_Scoring_Model!$C$14,IF(Q15>$I15,0,A_Scoring_Model!$C$15+(A_Scoring_Model!$C$14-A_Scoring_Model!$C$15)*($I15-Q15)/($I15-$H15)))))) -> 100
A16: 3.d-D2-05 | B16: D2 | C16: Reuse & genericity | D16: Generic | E16: Product lines / repo domains supported with ≤10% efficacy drop | F16: count | G16: Higher is better | H16: 3 | I16: 2 | J16: 3 | K16: =IF(J16="","",IF($H16=$I16,IF(OR(AND($G16="Higher is better",J16>=$H16),AND($G16="Lower is better",J16<=$H16)),A_Scoring_Model!$C$14,0),IF($G16="Higher is better",IF(J16>=$H16,A_Scoring_Model!$C$14,IF(J16<$I16,0,A_Scoring_Model!$C$15+(A_Scoring_Model!$C$14-A_Scoring_Model!$C$15)*(J16-$I16)/($H16-$I16))),IF(J16<=$H16,A_Scoring_Model!$C$14,IF(J16>$I16,0,A_Scoring_Model!$C$15+(A_Scoring_Model!$C$14-A_Scoring_Model!$C$15)*($I16-J16)/($I16-$H16)))))) -> 100 | L16: =IF(K16=100,"Meets target",IF(K16=0,"Below floor",IF(K16>=80,"Near target","Above floor"))) -> Meets target | M16: Medium | N16: 3 | O16: =IF(N16="","",IF($H16=$I16,IF(OR(AND($G16="Higher is better",N16>=$H16),AND($G16="Lower is better",N16<=$H16)),A_Scoring_Model!$C$14,0),IF($G16="Higher is better",IF(N16>=$H16,A_Scoring_Model!$C$14,IF(N16<$I16,0,A_Scoring_Model!$C$15+(A_Scoring_Model!$C$14-A_Scoring_Model!$C$15)*(N16-$I16)/($H16-$I16))),IF(N16<=$H16,A_Scoring_Model!$C$14,IF(N16>$I16,0,A_Scoring_Model!$C$15+(A_Scoring_Model!$C$14-A_Scoring_Model!$C$15)*($I16-N16)/($I16-$H16)))))) -> 100 | P16: Firmware (eMMC, NVMe test suites), backend services and frontend repos are all onboarded; no per-domain efficacy measurement exists. | Q16: 3 | R16: =IF(Q16="","",IF($H16=$I16,IF(OR(AND($G16="Higher is better",Q16>=$H16),AND($G16="Lower is better",Q16<=$H16)),A_Scoring_Model!$C$14,0),IF($G16="Higher is better",IF(Q16>=$H16,A_Scoring_Model!$C$14,IF(Q16<$I16,0,A_Scoring_Model!$C$15+(A_Scoring_Model!$C$14-A_Scoring_Model!$C$15)*(Q16-$I16)/($H16-$I16))),IF(Q16<=$H16,A_Scoring_Model!$C$14,IF(Q16>$I16,0,A_Scoring_Model!$C$15+(A_Scoring_Model!$C$14-A_Scoring_Model!$C$15)*($I16-Q16)/($I16-$H16)))))) -> 100
A17: 3.d-D2-06 | B17: D2 | C17: Reuse & genericity | D17: Generic | E17: Uses Zion shared services instead of re-implementing them | F17: Yes/No | G17: Higher is better | H17: 1 | I17: =IF(G17="Higher is better",H17*(1-A_Scoring_Model!$C$16),H17*(1+A_Scoring_Model!$C$16)) -> 0.8 | J17: 0 | K17: =IF(J17="","",IF($H17=$I17,IF(OR(AND($G17="Higher is better",J17>=$H17),AND($G17="Lower is better",J17<=$H17)),A_Scoring_Model!$C$14,0),IF($G17="Higher is better",IF(J17>=$H17,A_Scoring_Model!$C$14,IF(J17<$I17,0,A_Scoring_Model!$C$15+(A_Scoring_Model!$C$14-A_Scoring_Model!$C$15)*(J17-$I17)/($H17-$I17))),IF(J17<=$H17,A_Scoring_Model!$C$14,IF(J17>$I17,0,A_Scoring_Model!$C$15+(A_Scoring_Model!$C$14-A_Scoring_Model!$C$15)*($I17-J17)/($I17-$H17)))))) -> 0 | L17: =IF(K17=100,"Meets target",IF(K17=0,"Below floor",IF(K17>=80,"Near target","Above floor"))) -> Below floor | M17: High | N17: 1 | O17: =IF(N17="","",IF($H17=$I17,IF(OR(AND($G17="Higher is better",N17>=$H17),AND($G17="Lower is better",N17<=$H17)),A_Scoring_Model!$C$14,0),IF($G17="Higher is better",IF(N17>=$H17,A_Scoring_Model!$C$14,IF(N17<$I17,0,A_Scoring_Model!$C$15+(A_Scoring_Model!$C$14-A_Scoring_Model!$C$15)*(N17-$I17)/($H17-$I17))),IF(N17<=$H17,A_Scoring_Model!$C$14,IF(N17>$I17,0,A_Scoring_Model!$C$15+(A_Scoring_Model!$C$14-A_Scoring_Model!$C$15)*($I17-N17)/($I17-$H17)))))) -> 100 | P17: Maintains its own Graph RAG index (148.55 MB) and its own LLM calling path; not registered as a consumer of the shared embedding service or LLM gateway. | Q17: 0 | R17: =IF(Q17="","",IF($H17=$I17,IF(OR(AND($G17="Higher is better",Q17>=$H17),AND($G17="Lower is better",Q17<=$H17)),A_Scoring_Model!$C$14,0),IF($G17="Higher is better",IF(Q17>=$H17,A_Scoring_Model!$C$14,IF(Q17<$I17,0,A_Scoring_Model!$C$15+(A_Scoring_Model!$C$14-A_Scoring_Model!$C$15)*(Q17-$I17)/($H17-$I17))),IF(Q17<=$H17,A_Scoring_Model!$C$14,IF(Q17>$I17,0,A_Scoring_Model!$C$15+(A_Scoring_Model!$C$14-A_Scoring_Model!$C$15)*($I17-Q17)/($I17-$H17)))))) -> 0
A18: 3.d-D3-01 | B18: D3 | C18: Scalability & performance | D18: L3-3.d | E18: Average AI review latency per MR | F18: min | G18: Lower is better | H18: 5 | I18: 10 | J18: 2 | K18: =IF(J18="","",IF($H18=$I18,IF(OR(AND($G18="Higher is better",J18>=$H18),AND($G18="Lower is better",J18<=$H18)),A_Scoring_Model!$C$14,0),IF($G18="Higher is better",IF(J18>=$H18,A_Scoring_Model!$C$14,IF(J18<$I18,0,A_Scoring_Model!$C$15+(A_Scoring_Model!$C$14-A_Scoring_Model!$C$15)*(J18-$I18)/($H18-$I18))),IF(J18<=$H18,A_Scoring_Model!$C$14,IF(J18>$I18,0,A_Scoring_Model!$C$15+(A_Scoring_Model!$C$14-A_Scoring_Model!$C$15)*($I18-J18)/($I18-$H18)))))) -> 100 | L18: =IF(K18=100,"Meets target",IF(K18=0,"Below floor",IF(K18>=80,"Near target","Above floor"))) -> Meets target | M18: High | N18: 2 | O18: =IF(N18="","",IF($H18=$I18,IF(OR(AND($G18="Higher is better",N18>=$H18),AND($G18="Lower is better",N18<=$H18)),A_Scoring_Model!$C$14,0),IF($G18="Higher is better",IF(N18>=$H18,A_Scoring_Model!$C$14,IF(N18<$I18,0,A_Scoring_Model!$C$15+(A_Scoring_Model!$C$14-A_Scoring_Model!$C$15)*(N18-$I18)/($H18-$I18))),IF(N18<=$H18,A_Scoring_Model!$C$14,IF(N18>$I18,0,A_Scoring_Model!$C$15+(A_Scoring_Model!$C$14-A_Scoring_Model!$C$15)*($I18-N18)/($I18-$H18)))))) -> 100 | P18: Dashboard: average review time 2 minutes; recent reviews show 2–3 minutes against 11–62 minutes of manual effort. | Q18: 2 | R18: =IF(Q18="","",IF($H18=$I18,IF(OR(AND($G18="Higher is better",Q18>=$H18),AND($G18="Lower is better",Q18<=$H18)),A_Scoring_Model!$C$14,0),IF($G18="Higher is better",IF(Q18>=$H18,A_Scoring_Model!$C$14,IF(Q18<$I18,0,A_Scoring_Model!$C$15+(A_Scoring_Model!$C$14-A_Scoring_Model!$C$15)*(Q18-$I18)/($H18-$I18))),IF(Q18<=$H18,A_Scoring_Model!$C$14,IF(Q18>$I18,0,A_Scoring_Model!$C$15+(A_Scoring_Model!$C$14-A_Scoring_Model!$C$15)*($I18-Q18)/($I18-$H18)))))) -> 100
A19: 3.d-D3-02 | B19: D3 | C19: Scalability & performance | D19: L3-3.d | E19: Sustained review throughput | F19: reviews/day | G19: Higher is better | H19: 100 | I19: 50 | J19: 4.6 | K19: =IF(J19="","",IF($H19=$I19,IF(OR(AND($G19="Higher is better",J19>=$H19),AND($G19="Lower is better",J19<=$H19)),A_Scoring_Model!$C$14,0),IF($G19="Higher is better",IF(J19>=$H19,A_Scoring_Model!$C$14,IF(J19<$I19,0,A_Scoring_Model!$C$15+(A_Scoring_Model!$C$14-A_Scoring_Model!$C$15)*(J19-$I19)/($H19-$I19))),IF(J19<=$H19,A_Scoring_Model!$C$14,IF(J19>$I19,0,A_Scoring_Model!$C$15+(A_Scoring_Model!$C$14-A_Scoring_Model!$C$15)*($I19-J19)/($I19-$H19)))))) -> 0 | L19: =IF(K19=100,"Meets target",IF(K19=0,"Below floor",IF(K19>=80,"Near target","Above floor"))) -> Below floor | M19: High | N19: 60 | O19: =IF(N19="","",IF($H19=$I19,IF(OR(AND($G19="Higher is better",N19>=$H19),AND($G19="Lower is better",N19<=$H19)),A_Scoring_Model!$C$14,0),IF($G19="Higher is better",IF(N19>=$H19,A_Scoring_Model!$C$14,IF(N19<$I19,0,A_Scoring_Model!$C$15+(A_Scoring_Model!$C$14-A_Scoring_Model!$C$15)*(N19-$I19)/($H19-$I19))),IF(N19<=$H19,A_Scoring_Model!$C$14,IF(N19>$I19,0,A_Scoring_Model!$C$15+(A_Scoring_Model!$C$14-A_Scoring_Model!$C$15)*($I19-N19)/($I19-$H19)))))) -> 68 | P19: 32 reviews in the last 7 days ≈ 4.6 per day, against a target developer base of ~400 engineers and ~100 MRs per day. | Q19: 20 | R19: =IF(Q19="","",IF($H19=$I19,IF(OR(AND($G19="Higher is better",Q19>=$H19),AND($G19="Lower is better",Q19<=$H19)),A_Scoring_Model!$C$14,0),IF($G19="Higher is better",IF(Q19>=$H19,A_Scoring_Model!$C$14,IF(Q19<$I19,0,A_Scoring_Model!$C$15+(A_Scoring_Model!$C$14-A_Scoring_Model!$C$15)*(Q19-$I19)/($H19-$I19))),IF(Q19<=$H19,A_Scoring_Model!$C$14,IF(Q19>$I19,0,A_Scoring_Model!$C$15+(A_Scoring_Model!$C$14-A_Scoring_Model!$C$15)*($I19-Q19)/($I19-$H19)))))) -> 0
A20: 3.d-D3-03 | B20: D3 | C20: Scalability & performance | D20: L3-3.d | E20: LLM tokens consumed per review | F20: tokens | G20: Lower is better | H20: 50000 | I20: 75000 | J20: 87500 | K20: =IF(J20="","",IF($H20=$I20,IF(OR(AND($G20="Higher is better",J20>=$H20),AND($G20="Lower is better",J20<=$H20)),A_Scoring_Model!$C$14,0),IF($G20="Higher is better",IF(J20>=$H20,A_Scoring_Model!$C$14,IF(J20<$I20,0,A_Scoring_Model!$C$15+(A_Scoring_Model!$C$14-A_Scoring_Model!$C$15)*(J20-$I20)/($H20-$I20))),IF(J20<=$H20,A_Scoring_Model!$C$14,IF(J20>$I20,0,A_Scoring_Model!$C$15+(A_Scoring_Model!$C$14-A_Scoring_Model!$C$15)*($I20-J20)/($I20-$H20)))))) -> 0 | L20: =IF(K20=100,"Meets target",IF(K20=0,"Below floor",IF(K20>=80,"Near target","Above floor"))) -> Below floor | M20: High | N20: 55000 | O20: =IF(N20="","",IF($H20=$I20,IF(OR(AND($G20="Higher is better",N20>=$H20),AND($G20="Lower is better",N20<=$H20)),A_Scoring_Model!$C$14,0),IF($G20="Higher is better",IF(N20>=$H20,A_Scoring_Model!$C$14,IF(N20<$I20,0,A_Scoring_Model!$C$15+(A_Scoring_Model!$C$14-A_Scoring_Model!$C$15)*(N20-$I20)/($H20-$I20))),IF(N20<=$H20,A_Scoring_Model!$C$14,IF(N20>$I20,0,A_Scoring_Model!$C$15+(A_Scoring_Model!$C$14-A_Scoring_Model!$C$15)*($I20-N20)/($I20-$H20)))))) -> 92 | P20: 2.8M tokens over 32 reviews = 87.5K per review; 270 LLM calls = 8.4 calls per review at 10K tokens per call. | Q20: 60000 | R20: =IF(Q20="","",IF($H20=$I20,IF(OR(AND($G20="Higher is better",Q20>=$H20),AND($G20="Lower is better",Q20<=$H20)),A_Scoring_Model!$C$14,0),IF($G20="Higher is better",IF(Q20>=$H20,A_Scoring_Model!$C$14,IF(Q20<$I20,0,A_Scoring_Model!$C$15+(A_Scoring_Model!$C$14-A_Scoring_Model!$C$15)*(Q20-$I20)/($H20-$I20))),IF(Q20<=$H20,A_Scoring_Model!$C$14,IF(Q20>$I20,0,A_Scoring_Model!$C$15+(A_Scoring_Model!$C$14-A_Scoring_Model!$C$15)*($I20-Q20)/($I20-$H20)))))) -> 84
A21: 3.d-D3-04 | B21: D3 | C21: Scalability & performance | D21: L3-3.d | E21: Graph RAG index size per repository | F21: MB | G21: Lower is better | H21: 100 | I21: 200 | J21: 148.55 | K21: =IF(J21="","",IF($H21=$I21,IF(OR(AND($G21="Higher is better",J21>=$H21),AND($G21="Lower is better",J21<=$H21)),A_Scoring_Model!$C$14,0),IF($G21="Higher is better",IF(J21>=$H21,A_Scoring_Model!$C$14,IF(J21<$I21,0,A_Scoring_Model!$C$15+(A_Scoring_Model!$C$14-A_Scoring_Model!$C$15)*(J21-$I21)/($H21-$I21))),IF(J21<=$H21,A_Scoring_Model!$C$14,IF(J21>$I21,0,A_Scoring_Model!$C$15+(A_Scoring_Model!$C$14-A_Scoring_Model!$C$15)*($I21-J21)/($I21-$H21)))))) -> 80.58 | L21: =IF(K21=100,"Meets target",IF(K21=0,"Below floor",IF(K21>=80,"Near target","Above floor"))) -> Near target | M21: High | N21: 110 | O21: =IF(N21="","",IF($H21=$I21,IF(OR(AND($G21="Higher is better",N21>=$H21),AND($G21="Lower is better",N21<=$H21)),A_Scoring_Model!$C$14,0),IF($G21="Higher is better",IF(N21>=$H21,A_Scoring_Model!$C$14,IF(N21<$I21,0,A_Scoring_Model!$C$15+(A_Scoring_Model!$C$14-A_Scoring_Model!$C$15)*(N21-$I21)/($H21-$I21))),IF(N21<=$H21,A_Scoring_Model!$C$14,IF(N21>$I21,0,A_Scoring_Model!$C$15+(A_Scoring_Model!$C$14-A_Scoring_Model!$C$15)*($I21-N21)/($I21-$H21)))))) -> 96 | P21: Dashboard: Graph RAG size 148.55 MB average dependency size. At 92 repositories this projects to roughly 13.7 GB. | Q21: 148.55 | R21: =IF(Q21="","",IF($H21=$I21,IF(OR(AND($G21="Higher is better",Q21>=$H21),AND($G21="Lower is better",Q21<=$H21)),A_Scoring_Model!$C$14,0),IF($G21="Higher is better",IF(Q21>=$H21,A_Scoring_Model!$C$14,IF(Q21<$I21,0,A_Scoring_Model!$C$15+(A_Scoring_Model!$C$14-A_Scoring_Model!$C$15)*(Q21-$I21)/($H21-$I21))),IF(Q21<=$H21,A_Scoring_Model!$C$14,IF(Q21>$I21,0,A_Scoring_Model!$C$15+(A_Scoring_Model!$C$14-A_Scoring_Model!$C$15)*($I21-Q21)/($I21-$H21)))))) -> 80.58
A22: 3.d-D3-05 | B22: D3 | C22: Scalability & performance | D22: Generic | E22: Latency degradation at 10× load | F22: % | G22: Lower is better | H22: 0.2 | I22: 0.4 | J22: 0.3 | K22: =IF(J22="","",IF($H22=$I22,IF(OR(AND($G22="Higher is better",J22>=$H22),AND($G22="Lower is better",J22<=$H22)),A_Scoring_Model!$C$14,0),IF($G22="Higher is better",IF(J22>=$H22,A_Scoring_Model!$C$14,IF(J22<$I22,0,A_Scoring_Model!$C$15+(A_Scoring_Model!$C$14-A_Scoring_Model!$C$15)*(J22-$I22)/($H22-$I22))),IF(J22<=$H22,A_Scoring_Model!$C$14,IF(J22>$I22,0,A_Scoring_Model!$C$15+(A_Scoring_Model!$C$14-A_Scoring_Model!$C$15)*($I22-J22)/($I22-$H22)))))) -> 80 | L22: =IF(K22=100,"Meets target",IF(K22=0,"Below floor",IF(K22>=80,"Near target","Above floor"))) -> Near target | M22: Low | N22: 0.22 | O22: =IF(N22="","",IF($H22=$I22,IF(OR(AND($G22="Higher is better",N22>=$H22),AND($G22="Lower is better",N22<=$H22)),A_Scoring_Model!$C$14,0),IF($G22="Higher is better",IF(N22>=$H22,A_Scoring_Model!$C$14,IF(N22<$I22,0,A_Scoring_Model!$C$15+(A_Scoring_Model!$C$14-A_Scoring_Model!$C$15)*(N22-$I22)/($H22-$I22))),IF(N22<=$H22,A_Scoring_Model!$C$14,IF(N22>$I22,0,A_Scoring_Model!$C$15+(A_Scoring_Model!$C$14-A_Scoring_Model!$C$15)*($I22-N22)/($I22-$H22)))))) -> 96 | P22: No load test evidenced. Estimated from the current 4.6 reviews/day baseline versus the ~100 MRs/day target. | Q22: 0.3 | R22: =IF(Q22="","",IF($H22=$I22,IF(OR(AND($G22="Higher is better",Q22>=$H22),AND($G22="Lower is better",Q22<=$H22)),A_Scoring_Model!$C$14,0),IF($G22="Higher is better",IF(Q22>=$H22,A_Scoring_Model!$C$14,IF(Q22<$I22,0,A_Scoring_Model!$C$15+(A_Scoring_Model!$C$14-A_Scoring_Model!$C$15)*(Q22-$I22)/($H22-$I22))),IF(Q22<=$H22,A_Scoring_Model!$C$14,IF(Q22>$I22,0,A_Scoring_Model!$C$15+(A_Scoring_Model!$C$14-A_Scoring_Model!$C$15)*($I22-Q22)/($I22-$H22)))))) -> 80
A23: 3.d-D4-01 | B23: D4 | C23: Reliability & trust | D23: L3-3.d | E23: Hallucinated findings (non-existent code, fields or APIs) | F23: % | G23: Lower is better | H23: 0.02 | I23: 0.05 | J23: 0.1 | K23: =IF(J23="","",IF($H23=$I23,IF(OR(AND($G23="Higher is better",J23>=$H23),AND($G23="Lower is better",J23<=$H23)),A_Scoring_Model!$C$14,0),IF($G23="Higher is better",IF(J23>=$H23,A_Scoring_Model!$C$14,IF(J23<$I23,0,A_Scoring_Model!$C$15+(A_Scoring_Model!$C$14-A_Scoring_Model!$C$15)*(J23-$I23)/($H23-$I23))),IF(J23<=$H23,A_Scoring_Model!$C$14,IF(J23>$I23,0,A_Scoring_Model!$C$15+(A_Scoring_Model!$C$14-A_Scoring_Model!$C$15)*($I23-J23)/($I23-$H23)))))) -> 0 | L23: =IF(K23=100,"Meets target",IF(K23=0,"Below floor",IF(K23>=80,"Near target","Above floor"))) -> Below floor | M23: Low | N23: 0.03 | O23: =IF(N23="","",IF($H23=$I23,IF(OR(AND($G23="Higher is better",N23>=$H23),AND($G23="Lower is better",N23<=$H23)),A_Scoring_Model!$C$14,0),IF($G23="Higher is better",IF(N23>=$H23,A_Scoring_Model!$C$14,IF(N23<$I23,0,A_Scoring_Model!$C$15+(A_Scoring_Model!$C$14-A_Scoring_Model!$C$15)*(N23-$I23)/($H23-$I23))),IF(N23<=$H23,A_Scoring_Model!$C$14,IF(N23>$I23,0,A_Scoring_Model!$C$15+(A_Scoring_Model!$C$14-A_Scoring_Model!$C$15)*($I23-N23)/($I23-$H23)))))) -> 86.666667 | P23: Not measured. Estimated: Graph RAG context reduces hallucination, but 0% issue resolution suggests a material share of findings do not hold up. | Q23: 0.05 | R23: =IF(Q23="","",IF($H23=$I23,IF(OR(AND($G23="Higher is better",Q23>=$H23),AND($G23="Lower is better",Q23<=$H23)),A_Scoring_Model!$C$14,0),IF($G23="Higher is better",IF(Q23>=$H23,A_Scoring_Model!$C$14,IF(Q23<$I23,0,A_Scoring_Model!$C$15+(A_Scoring_Model!$C$14-A_Scoring_Model!$C$15)*(Q23-$I23)/($H23-$I23))),IF(Q23<=$H23,A_Scoring_Model!$C$14,IF(Q23>$I23,0,A_Scoring_Model!$C$15+(A_Scoring_Model!$C$14-A_Scoring_Model!$C$15)*($I23-Q23)/($I23-$H23)))))) -> 60
A24: 3.d-D4-02 | B24: D4 | C24: Reliability & trust | D24: L3-3.d | E24: Findings carrying exact file, line and severity | F24: % | G24: Higher is better | H24: 1 | I24: 0.95 | J24: 0.95 | K24: =IF(J24="","",IF($H24=$I24,IF(OR(AND($G24="Higher is better",J24>=$H24),AND($G24="Lower is better",J24<=$H24)),A_Scoring_Model!$C$14,0),IF($G24="Higher is better",IF(J24>=$H24,A_Scoring_Model!$C$14,IF(J24<$I24,0,A_Scoring_Model!$C$15+(A_Scoring_Model!$C$14-A_Scoring_Model!$C$15)*(J24-$I24)/($H24-$I24))),IF(J24<=$H24,A_Scoring_Model!$C$14,IF(J24>$I24,0,A_Scoring_Model!$C$15+(A_Scoring_Model!$C$14-A_Scoring_Model!$C$15)*($I24-J24)/($I24-$H24)))))) -> 60 | L24: =IF(K24=100,"Meets target",IF(K24=0,"Below floor",IF(K24>=80,"Near target","Above floor"))) -> Above floor | M24: High | N24: 1 | O24: =IF(N24="","",IF($H24=$I24,IF(OR(AND($G24="Higher is better",N24>=$H24),AND($G24="Lower is better",N24<=$H24)),A_Scoring_Model!$C$14,0),IF($G24="Higher is better",IF(N24>=$H24,A_Scoring_Model!$C$14,IF(N24<$I24,0,A_Scoring_Model!$C$15+(A_Scoring_Model!$C$14-A_Scoring_Model!$C$15)*(N24-$I24)/($H24-$I24))),IF(N24<=$H24,A_Scoring_Model!$C$14,IF(N24>$I24,0,A_Scoring_Model!$C$15+(A_Scoring_Model!$C$14-A_Scoring_Model!$C$15)*($I24-N24)/($I24-$H24)))))) -> 100 | P24: System prompt v2 requires exact relative path and a single integer line for every comment; dashboard renders per-PR inline comments. | Q24: 1 | R24: =IF(Q24="","",IF($H24=$I24,IF(OR(AND($G24="Higher is better",Q24>=$H24),AND($G24="Lower is better",Q24<=$H24)),A_Scoring_Model!$C$14,0),IF($G24="Higher is better",IF(Q24>=$H24,A_Scoring_Model!$C$14,IF(Q24<$I24,0,A_Scoring_Model!$C$15+(A_Scoring_Model!$C$14-A_Scoring_Model!$C$15)*(Q24-$I24)/($H24-$I24))),IF(Q24<=$H24,A_Scoring_Model!$C$14,IF(Q24>$I24,0,A_Scoring_Model!$C$15+(A_Scoring_Model!$C$14-A_Scoring_Model!$C$15)*($I24-Q24)/($I24-$H24)))))) -> 100
A25: 3.d-D4-03 | B25: D4 | C25: Reliability & trust | D25: L3-3.d | E25: Run-to-run consistency on the same MR | F25: % | G25: Higher is better | H25: 0.95 | I25: 0.9 | J25: 0.75 | K25: =IF(J25="","",IF($H25=$I25,IF(OR(AND($G25="Higher is better",J25>=$H25),AND($G25="Lower is better",J25<=$H25)),A_Scoring_Model!$C$14,0),IF($G25="Higher is better",IF(J25>=$H25,A_Scoring_Model!$C$14,IF(J25<$I25,0,A_Scoring_Model!$C$15+(A_Scoring_Model!$C$14-A_Scoring_Model!$C$15)*(J25-$I25)/($H25-$I25))),IF(J25<=$H25,A_Scoring_Model!$C$14,IF(J25>$I25,0,A_Scoring_Model!$C$15+(A_Scoring_Model!$C$14-A_Scoring_Model!$C$15)*($I25-J25)/($I25-$H25)))))) -> 0 | L25: =IF(K25=100,"Meets target",IF(K25=0,"Below floor",IF(K25>=80,"Near target","Above floor"))) -> Below floor | M25: Low | N25: 0.93 | O25: =IF(N25="","",IF($H25=$I25,IF(OR(AND($G25="Higher is better",N25>=$H25),AND($G25="Lower is better",N25<=$H25)),A_Scoring_Model!$C$14,0),IF($G25="Higher is better",IF(N25>=$H25,A_Scoring_Model!$C$14,IF(N25<$I25,0,A_Scoring_Model!$C$15+(A_Scoring_Model!$C$14-A_Scoring_Model!$C$15)*(N25-$I25)/($H25-$I25))),IF(N25<=$H25,A_Scoring_Model!$C$14,IF(N25>$I25,0,A_Scoring_Model!$C$15+(A_Scoring_Model!$C$14-A_Scoring_Model!$C$15)*($I25-N25)/($I25-$H25)))))) -> 84 | P25: Not measured. LLM temperature and seed handling not evidenced in the system prompt or pipeline documentation. | Q25: 0.9 | R25: =IF(Q25="","",IF($H25=$I25,IF(OR(AND($G25="Higher is better",Q25>=$H25),AND($G25="Lower is better",Q25<=$H25)),A_Scoring_Model!$C$14,0),IF($G25="Higher is better",IF(Q25>=$H25,A_Scoring_Model!$C$14,IF(Q25<$I25,0,A_Scoring_Model!$C$15+(A_Scoring_Model!$C$14-A_Scoring_Model!$C$15)*(Q25-$I25)/($H25-$I25))),IF(Q25<=$H25,A_Scoring_Model!$C$14,IF(Q25>$I25,0,A_Scoring_Model!$C$15+(A_Scoring_Model!$C$14-A_Scoring_Model!$C$15)*($I25-Q25)/($I25-$H25)))))) -> 60
A26: 3.d-D4-04 | B26: D4 | C26: Reliability & trust | D26: L3-3.d | E26: Human approves every merge (advisory comments only) | F26: Yes/No | G26: Higher is better | H26: 1 | I26: =IF(G26="Higher is better",H26*(1-A_Scoring_Model!$C$16),H26*(1+A_Scoring_Model!$C$16)) -> 0.8 | J26: 1 | K26: =IF(J26="","",IF($H26=$I26,IF(OR(AND($G26="Higher is better",J26>=$H26),AND($G26="Lower is better",J26<=$H26)),A_Scoring_Model!$C$14,0),IF($G26="Higher is better",IF(J26>=$H26,A_Scoring_Model!$C$14,IF(J26<$I26,0,A_Scoring_Model!$C$15+(A_Scoring_Model!$C$14-A_Scoring_Model!$C$15)*(J26-$I26)/($H26-$I26))),IF(J26<=$H26,A_Scoring_Model!$C$14,IF(J26>$I26,0,A_Scoring_Model!$C$15+(A_Scoring_Model!$C$14-A_Scoring_Model!$C$15)*($I26-J26)/($I26-$H26)))))) -> 100 | L26: =IF(K26=100,"Meets target",IF(K26=0,"Below floor",IF(K26>=80,"Near target","Above floor"))) -> Meets target | M26: High | N26: 1 | O26: =IF(N26="","",IF($H26=$I26,IF(OR(AND($G26="Higher is better",N26>=$H26),AND($G26="Lower is better",N26<=$H26)),A_Scoring_Model!$C$14,0),IF($G26="Higher is better",IF(N26>=$H26,A_Scoring_Model!$C$14,IF(N26<$I26,0,A_Scoring_Model!$C$15+(A_Scoring_Model!$C$14-A_Scoring_Model!$C$15)*(N26-$I26)/($H26-$I26))),IF(N26<=$H26,A_Scoring_Model!$C$14,IF(N26>$I26,0,A_Scoring_Model!$C$15+(A_Scoring_Model!$C$14-A_Scoring_Model!$C$15)*($I26-N26)/($I26-$H26)))))) -> 100 | P26: Review Shield posts comments on MRs; merge and resolution stay with the developer and reviewer (PR state OPEN / MERGED shown in the dashboard). | Q26: 1 | R26: =IF(Q26="","",IF($H26=$I26,IF(OR(AND($G26="Higher is better",Q26>=$H26),AND($G26="Lower is better",Q26<=$H26)),A_Scoring_Model!$C$14,0),IF($G26="Higher is better",IF(Q26>=$H26,A_Scoring_Model!$C$14,IF(Q26<$I26,0,A_Scoring_Model!$C$15+(A_Scoring_Model!$C$14-A_Scoring_Model!$C$15)*(Q26-$I26)/($H26-$I26))),IF(Q26<=$H26,A_Scoring_Model!$C$14,IF(Q26>$I26,0,A_Scoring_Model!$C$15+(A_Scoring_Model!$C$14-A_Scoring_Model!$C$15)*($I26-Q26)/($I26-$H26)))))) -> 100
A27: 3.d-D4-05 | B27: D4 | C27: Reliability & trust | D27: Generic | E27: Service availability | F27: % | G27: Higher is better | H27: 0.995 | I27: 0.99 | J27: 0.99 | K27: =IF(J27="","",IF($H27=$I27,IF(OR(AND($G27="Higher is better",J27>=$H27),AND($G27="Lower is better",J27<=$H27)),A_Scoring_Model!$C$14,0),IF($G27="Higher is better",IF(J27>=$H27,A_Scoring_Model!$C$14,IF(J27<$I27,0,A_Scoring_Model!$C$15+(A_Scoring_Model!$C$14-A_Scoring_Model!$C$15)*(J27-$I27)/($H27-$I27))),IF(J27<=$H27,A_Scoring_Model!$C$14,IF(J27>$I27,0,A_Scoring_Model!$C$15+(A_Scoring_Model!$C$14-A_Scoring_Model!$C$15)*($I27-J27)/($I27-$H27)))))) -> 60 | L27: =IF(K27=100,"Meets target",IF(K27=0,"Below floor",IF(K27>=80,"Near target","Above floor"))) -> Above floor | M27: Low | N27: 0.995 | O27: =IF(N27="","",IF($H27=$I27,IF(OR(AND($G27="Higher is better",N27>=$H27),AND($G27="Lower is better",N27<=$H27)),A_Scoring_Model!$C$14,0),IF($G27="Higher is better",IF(N27>=$H27,A_Scoring_Model!$C$14,IF(N27<$I27,0,A_Scoring_Model!$C$15+(A_Scoring_Model!$C$14-A_Scoring_Model!$C$15)*(N27-$I27)/($H27-$I27))),IF(N27<=$H27,A_Scoring_Model!$C$14,IF(N27>$I27,0,A_Scoring_Model!$C$15+(A_Scoring_Model!$C$14-A_Scoring_Model!$C$15)*($I27-N27)/($I27-$H27)))))) -> 100 | P27: No SLA dashboard or uptime report evidenced; estimated from continuous operation across 11 onboarded repositories. | Q27: 0.99 | R27: =IF(Q27="","",IF($H27=$I27,IF(OR(AND($G27="Higher is better",Q27>=$H27),AND($G27="Lower is better",Q27<=$H27)),A_Scoring_Model!$C$14,0),IF($G27="Higher is better",IF(Q27>=$H27,A_Scoring_Model!$C$14,IF(Q27<$I27,0,A_Scoring_Model!$C$15+(A_Scoring_Model!$C$14-A_Scoring_Model!$C$15)*(Q27-$I27)/($H27-$I27))),IF(Q27<=$H27,A_Scoring_Model!$C$14,IF(Q27>$I27,0,A_Scoring_Model!$C$15+(A_Scoring_Model!$C$14-A_Scoring_Model!$C$15)*($I27-Q27)/($I27-$H27)))))) -> 60
A28: 3.d-D5-01 | B28: D5 | C28: Business value | D28: L3-3.d | E28: Human review effort saved per MR | F28: % | G28: Higher is better | H28: 0.6 | I28: 0.4 | J28: 0.977 | K28: =IF(J28="","",IF($H28=$I28,IF(OR(AND($G28="Higher is better",J28>=$H28),AND($G28="Lower is better",J28<=$H28)),A_Scoring_Model!$C$14,0),IF($G28="Higher is better",IF(J28>=$H28,A_Scoring_Model!$C$14,IF(J28<$I28,0,A_Scoring_Model!$C$15+(A_Scoring_Model!$C$14-A_Scoring_Model!$C$15)*(J28-$I28)/($H28-$I28))),IF(J28<=$H28,A_Scoring_Model!$C$14,IF(J28>$I28,0,A_Scoring_Model!$C$15+(A_Scoring_Model!$C$14-A_Scoring_Model!$C$15)*($I28-J28)/($I28-$H28)))))) -> 100 | L28: =IF(K28=100,"Meets target",IF(K28=0,"Below floor",IF(K28>=80,"Near target","Above floor"))) -> Meets target | M28: Medium | N28: 0.977 | O28: =IF(N28="","",IF($H28=$I28,IF(OR(AND($G28="Higher is better",N28>=$H28),AND($G28="Lower is better",N28<=$H28)),A_Scoring_Model!$C$14,0),IF($G28="Higher is better",IF(N28>=$H28,A_Scoring_Model!$C$14,IF(N28<$I28,0,A_Scoring_Model!$C$15+(A_Scoring_Model!$C$14-A_Scoring_Model!$C$15)*(N28-$I28)/($H28-$I28))),IF(N28<=$H28,A_Scoring_Model!$C$14,IF(N28>$I28,0,A_Scoring_Model!$C$15+(A_Scoring_Model!$C$14-A_Scoring_Model!$C$15)*($I28-N28)/($I28-$H28)))))) -> 100 | P28: Dashboard: 97.7% average human effort saving; e.g. 2 min AI vs 62 min manual on a 706-LOC PR. Derived from an effort model, not a controlled study. | Q28: 0.977 | R28: =IF(Q28="","",IF($H28=$I28,IF(OR(AND($G28="Higher is better",Q28>=$H28),AND($G28="Lower is better",Q28<=$H28)),A_Scoring_Model!$C$14,0),IF($G28="Higher is better",IF(Q28>=$H28,A_Scoring_Model!$C$14,IF(Q28<$I28,0,A_Scoring_Model!$C$15+(A_Scoring_Model!$C$14-A_Scoring_Model!$C$15)*(Q28-$I28)/($H28-$I28))),IF(Q28<=$H28,A_Scoring_Model!$C$14,IF(Q28>$I28,0,A_Scoring_Model!$C$15+(A_Scoring_Model!$C$14-A_Scoring_Model!$C$15)*($I28-Q28)/($I28-$H28)))))) -> 100
A29: 3.d-D5-02 | B29: D5 | C29: Business value | D29: L3-3.d | E29: Engineer-hours saved per week | F29: hours | G29: Higher is better | H29: 40 | I29: 20 | J29: 50 | K29: =IF(J29="","",IF($H29=$I29,IF(OR(AND($G29="Higher is better",J29>=$H29),AND($G29="Lower is better",J29<=$H29)),A_Scoring_Model!$C$14,0),IF($G29="Higher is better",IF(J29>=$H29,A_Scoring_Model!$C$14,IF(J29<$I29,0,A_Scoring_Model!$C$15+(A_Scoring_Model!$C$14-A_Scoring_Model!$C$15)*(J29-$I29)/($H29-$I29))),IF(J29<=$H29,A_Scoring_Model!$C$14,IF(J29>$I29,0,A_Scoring_Model!$C$15+(A_Scoring_Model!$C$14-A_Scoring_Model!$C$15)*($I29-J29)/($I29-$H29)))))) -> 100 | L29: =IF(K29=100,"Meets target",IF(K29=0,"Below floor",IF(K29>=80,"Near target","Above floor"))) -> Meets target | M29: Medium | N29: 90 | O29: =IF(N29="","",IF($H29=$I29,IF(OR(AND($G29="Higher is better",N29>=$H29),AND($G29="Lower is better",N29<=$H29)),A_Scoring_Model!$C$14,0),IF($G29="Higher is better",IF(N29>=$H29,A_Scoring_Model!$C$14,IF(N29<$I29,0,A_Scoring_Model!$C$15+(A_Scoring_Model!$C$14-A_Scoring_Model!$C$15)*(N29-$I29)/($H29-$I29))),IF(N29<=$H29,A_Scoring_Model!$C$14,IF(N29>$I29,0,A_Scoring_Model!$C$15+(A_Scoring_Model!$C$14-A_Scoring_Model!$C$15)*($I29-N29)/($I29-$H29)))))) -> 100 | P29: Dashboard: 50 hours saved in the last 7 days across 32 reviews. | Q29: 60 | R29: =IF(Q29="","",IF($H29=$I29,IF(OR(AND($G29="Higher is better",Q29>=$H29),AND($G29="Lower is better",Q29<=$H29)),A_Scoring_Model!$C$14,0),IF($G29="Higher is better",IF(Q29>=$H29,A_Scoring_Model!$C$14,IF(Q29<$I29,0,A_Scoring_Model!$C$15+(A_Scoring_Model!$C$14-A_Scoring_Model!$C$15)*(Q29-$I29)/($H29-$I29))),IF(Q29<=$H29,A_Scoring_Model!$C$14,IF(Q29>$I29,0,A_Scoring_Model!$C$15+(A_Scoring_Model!$C$14-A_Scoring_Model!$C$15)*($I29-Q29)/($I29-$H29)))))) -> 100
A30: 3.d-D5-03 | B30: D5 | C30: Business value | D30: L3-3.d | E30: Issue resolution rate in merged PRs | F30: % | G30: Higher is better | H30: 0.7 | I30: 0.5 | J30: 0 | K30: =IF(J30="","",IF($H30=$I30,IF(OR(AND($G30="Higher is better",J30>=$H30),AND($G30="Lower is better",J30<=$H30)),A_Scoring_Model!$C$14,0),IF($G30="Higher is better",IF(J30>=$H30,A_Scoring_Model!$C$14,IF(J30<$I30,0,A_Scoring_Model!$C$15+(A_Scoring_Model!$C$14-A_Scoring_Model!$C$15)*(J30-$I30)/($H30-$I30))),IF(J30<=$H30,A_Scoring_Model!$C$14,IF(J30>$I30,0,A_Scoring_Model!$C$15+(A_Scoring_Model!$C$14-A_Scoring_Model!$C$15)*($I30-J30)/($I30-$H30)))))) -> 0 | L30: =IF(K30=100,"Meets target",IF(K30=0,"Below floor",IF(K30>=80,"Near target","Above floor"))) -> Below floor | M30: High | N30: 0.6 | O30: =IF(N30="","",IF($H30=$I30,IF(OR(AND($G30="Higher is better",N30>=$H30),AND($G30="Lower is better",N30<=$H30)),A_Scoring_Model!$C$14,0),IF($G30="Higher is better",IF(N30>=$H30,A_Scoring_Model!$C$14,IF(N30<$I30,0,A_Scoring_Model!$C$15+(A_Scoring_Model!$C$14-A_Scoring_Model!$C$15)*(N30-$I30)/($H30-$I30))),IF(N30<=$H30,A_Scoring_Model!$C$14,IF(N30>$I30,0,A_Scoring_Model!$C$15+(A_Scoring_Model!$C$14-A_Scoring_Model!$C$15)*($I30-N30)/($I30-$H30)))))) -> 80 | P30: Dashboard acceptance ratio: 0% — 0 resolved out of 56 issues found in merged PRs. The single most damaging metric in this evaluation. | Q30: 0.52 | R30: =IF(Q30="","",IF($H30=$I30,IF(OR(AND($G30="Higher is better",Q30>=$H30),AND($G30="Lower is better",Q30<=$H30)),A_Scoring_Model!$C$14,0),IF($G30="Higher is better",IF(Q30>=$H30,A_Scoring_Model!$C$14,IF(Q30<$I30,0,A_Scoring_Model!$C$15+(A_Scoring_Model!$C$14-A_Scoring_Model!$C$15)*(Q30-$I30)/($H30-$I30))),IF(Q30<=$H30,A_Scoring_Model!$C$14,IF(Q30>$I30,0,A_Scoring_Model!$C$15+(A_Scoring_Model!$C$14-A_Scoring_Model!$C$15)*($I30-Q30)/($I30-$H30)))))) -> 64
A31: 3.d-D5-04 | B31: D5 | C31: Business value | D31: L3-3.d | E31: Repositories onboarded (share of active repositories) | F31: % | G31: Higher is better | H31: 0.5 | I31: 0.3 | J31: 0.19 | K31: =IF(J31="","",IF($H31=$I31,IF(OR(AND($G31="Higher is better",J31>=$H31),AND($G31="Lower is better",J31<=$H31)),A_Scoring_Model!$C$14,0),IF($G31="Higher is better",IF(J31>=$H31,A_Scoring_Model!$C$14,IF(J31<$I31,0,A_Scoring_Model!$C$15+(A_Scoring_Model!$C$14-A_Scoring_Model!$C$15)*(J31-$I31)/($H31-$I31))),IF(J31<=$H31,A_Scoring_Model!$C$14,IF(J31>$I31,0,A_Scoring_Model!$C$15+(A_Scoring_Model!$C$14-A_Scoring_Model!$C$15)*($I31-J31)/($I31-$H31)))))) -> 0 | L31: =IF(K31=100,"Meets target",IF(K31=0,"Below floor",IF(K31>=80,"Near target","Above floor"))) -> Below floor | M31: High | N31: 0.45 | O31: =IF(N31="","",IF($H31=$I31,IF(OR(AND($G31="Higher is better",N31>=$H31),AND($G31="Lower is better",N31<=$H31)),A_Scoring_Model!$C$14,0),IF($G31="Higher is better",IF(N31>=$H31,A_Scoring_Model!$C$14,IF(N31<$I31,0,A_Scoring_Model!$C$15+(A_Scoring_Model!$C$14-A_Scoring_Model!$C$15)*(N31-$I31)/($H31-$I31))),IF(N31<=$H31,A_Scoring_Model!$C$14,IF(N31>$I31,0,A_Scoring_Model!$C$15+(A_Scoring_Model!$C$14-A_Scoring_Model!$C$15)*($I31-N31)/($I31-$H31)))))) -> 90 | P31: Dashboard: 11 of 58 repositories onboarded (19%); project view shows 92 total repositories, 28 active in the past 3 months. | Q31: 0.3 | R31: =IF(Q31="","",IF($H31=$I31,IF(OR(AND($G31="Higher is better",Q31>=$H31),AND($G31="Lower is better",Q31<=$H31)),A_Scoring_Model!$C$14,0),IF($G31="Higher is better",IF(Q31>=$H31,A_Scoring_Model!$C$14,IF(Q31<$I31,0,A_Scoring_Model!$C$15+(A_Scoring_Model!$C$14-A_Scoring_Model!$C$15)*(Q31-$I31)/($H31-$I31))),IF(Q31<=$H31,A_Scoring_Model!$C$14,IF(Q31>$I31,0,A_Scoring_Model!$C$15+(A_Scoring_Model!$C$14-A_Scoring_Model!$C$15)*($I31-Q31)/($I31-$H31)))))) -> 60
